2024-04-14 18:33:36,844 INFO    StreamThr :2088 [internal.py:wandb_internal():86] W&B internal server running at pid: 2088, started at: 2024-04-14 18:33:36.843145
2024-04-14 18:33:36,845 DEBUG   HandlerThread:2088 [handler.py:handle_request():146] handle_request: status
2024-04-14 18:33:36,850 INFO    WriterThread:2088 [datastore.py:open_for_write():87] open: /Users/a58/Downloads/MoE_Train/finetune/wandb/run-20240414_183336-fa4vztml/run-fa4vztml.wandb
2024-04-14 18:33:36,850 DEBUG   SenderThread:2088 [sender.py:send():379] send: header
2024-04-14 18:33:36,897 DEBUG   SenderThread:2088 [sender.py:send():379] send: run
2024-04-14 18:33:37,206 DEBUG   HandlerThread:2088 [handler.py:handle_request():146] handle_request: shutdown
2024-04-14 18:33:37,206 INFO    HandlerThread:2088 [handler.py:finish():866] shutting down handler
2024-04-14 18:33:37,537 INFO    SenderThread:2088 [dir_watcher.py:__init__():211] watching files in: /Users/a58/Downloads/MoE_Train/finetune/wandb/run-20240414_183336-fa4vztml/files
2024-04-14 18:33:37,537 INFO    SenderThread:2088 [sender.py:_start_run_threads():1124] run started: fa4vztml with start time 1713090816.84429
2024-04-14 18:33:37,537 INFO    SenderThread:2088 [sender.py:finish():1546] shutting down sender
2024-04-14 18:33:37,537 INFO    SenderThread:2088 [dir_watcher.py:finish():358] shutting down directory watcher
2024-04-14 18:33:37,902 INFO    WriterThread:2088 [datastore.py:close():296] close: /Users/a58/Downloads/MoE_Train/finetune/wandb/run-20240414_183336-fa4vztml/run-fa4vztml.wandb
2024-04-14 18:33:38,543 INFO    SenderThread:2088 [dir_watcher.py:finish():388] scan: /Users/a58/Downloads/MoE_Train/finetune/wandb/run-20240414_183336-fa4vztml/files
2024-04-14 18:33:38,544 INFO    SenderThread:2088 [dir_watcher.py:finish():402] scan save: /Users/a58/Downloads/MoE_Train/finetune/wandb/run-20240414_183336-fa4vztml/files/config.yaml config.yaml
2024-04-14 18:33:38,544 INFO    SenderThread:2088 [file_pusher.py:finish():172] shutting down file pusher
2024-04-14 18:33:38,548 INFO    SenderThread:2088 [file_pusher.py:join():178] waiting for file pusher
2024-04-14 18:33:39,178 ERROR   wandb-upload_0:2088 [internal_api.py:upload_file():2767] upload_file exception https://storage.googleapis.com/wandb-production.appspot.com/darren_qing/Moe_finetuning/fa4vztml/config.yaml?Expires=1713177219&GoogleAccessId=gorilla-files-url-signer-man%40wandb-production.iam.gserviceaccount.com&Signature=Vkmzp9B5uWxH%2BSlAaEicUuY7%2Ft6B3mY7BY3zVzzFSlq95BAEGkgPS6nMk%2FVS8rb8MwgaZRaRu6TBXR%2BBMyBKlCytqun9DpmwILPwkS3fDlpl6cvaNDuic9m89oBGFfxk%2Fb3924nGxVHPUUsEQbsXKwl%2FHICdqwl2iIL4ag8Ycxl%2BNnJjC01yler8QmEpfzluZ3hz9DvggbKVYsW3LcuJtW2c1OSgXzANfqqQWl0X3u%2FbUXjR%2FO31tT60Zozwaj27GaL27%2BiKyLmbu50kZZb3USD92ViJQGENX5Byo8D1N18XgHqHUjsIRIwLZlESmVu7P2ehfLxCohGZ3X64eJ8DJA%3D%3D: ('Connection aborted.', ConnectionResetError(54, 'Connection reset by peer'))
2024-04-14 18:33:39,178 ERROR   wandb-upload_0:2088 [internal_api.py:upload_file():2769] upload_file request headers: {'User-Agent': 'python-requests/2.31.0', 'Accept-Encoding': 'gzip, deflate, br', 'Accept': '*/*', 'Connection': 'keep-alive', 'Content-Length': '500'}
2024-04-14 18:33:39,179 ERROR   wandb-upload_0:2088 [internal_api.py:upload_file():2771] upload_file response body: 
2024-04-14 18:33:40,589 ERROR   wandb-upload_0:2088 [internal_api.py:upload_file():2767] upload_file exception https://storage.googleapis.com/wandb-production.appspot.com/darren_qing/Moe_finetuning/fa4vztml/config.yaml?Expires=1713177219&GoogleAccessId=gorilla-files-url-signer-man%40wandb-production.iam.gserviceaccount.com&Signature=Vkmzp9B5uWxH%2BSlAaEicUuY7%2Ft6B3mY7BY3zVzzFSlq95BAEGkgPS6nMk%2FVS8rb8MwgaZRaRu6TBXR%2BBMyBKlCytqun9DpmwILPwkS3fDlpl6cvaNDuic9m89oBGFfxk%2Fb3924nGxVHPUUsEQbsXKwl%2FHICdqwl2iIL4ag8Ycxl%2BNnJjC01yler8QmEpfzluZ3hz9DvggbKVYsW3LcuJtW2c1OSgXzANfqqQWl0X3u%2FbUXjR%2FO31tT60Zozwaj27GaL27%2BiKyLmbu50kZZb3USD92ViJQGENX5Byo8D1N18XgHqHUjsIRIwLZlESmVu7P2ehfLxCohGZ3X64eJ8DJA%3D%3D: ('Connection aborted.', ConnectionResetError(54, 'Connection reset by peer'))
2024-04-14 18:33:40,589 ERROR   wandb-upload_0:2088 [internal_api.py:upload_file():2769] upload_file request headers: {'User-Agent': 'python-requests/2.31.0', 'Accept-Encoding': 'gzip, deflate, br', 'Accept': '*/*', 'Connection': 'keep-alive', 'Content-Length': '500'}
2024-04-14 18:33:40,589 ERROR   wandb-upload_0:2088 [internal_api.py:upload_file():2771] upload_file response body: 
2024-04-14 18:33:42,767 ERROR   wandb-upload_0:2088 [internal_api.py:upload_file():2767] upload_file exception https://storage.googleapis.com/wandb-production.appspot.com/darren_qing/Moe_finetuning/fa4vztml/config.yaml?Expires=1713177219&GoogleAccessId=gorilla-files-url-signer-man%40wandb-production.iam.gserviceaccount.com&Signature=Vkmzp9B5uWxH%2BSlAaEicUuY7%2Ft6B3mY7BY3zVzzFSlq95BAEGkgPS6nMk%2FVS8rb8MwgaZRaRu6TBXR%2BBMyBKlCytqun9DpmwILPwkS3fDlpl6cvaNDuic9m89oBGFfxk%2Fb3924nGxVHPUUsEQbsXKwl%2FHICdqwl2iIL4ag8Ycxl%2BNnJjC01yler8QmEpfzluZ3hz9DvggbKVYsW3LcuJtW2c1OSgXzANfqqQWl0X3u%2FbUXjR%2FO31tT60Zozwaj27GaL27%2BiKyLmbu50kZZb3USD92ViJQGENX5Byo8D1N18XgHqHUjsIRIwLZlESmVu7P2ehfLxCohGZ3X64eJ8DJA%3D%3D: ('Connection aborted.', ConnectionResetError(54, 'Connection reset by peer'))
2024-04-14 18:33:42,768 ERROR   wandb-upload_0:2088 [internal_api.py:upload_file():2769] upload_file request headers: {'User-Agent': 'python-requests/2.31.0', 'Accept-Encoding': 'gzip, deflate, br', 'Accept': '*/*', 'Connection': 'keep-alive', 'Content-Length': '500'}
2024-04-14 18:33:42,768 ERROR   wandb-upload_0:2088 [internal_api.py:upload_file():2771] upload_file response body: 
2024-04-14 18:33:42,768 INFO    wandb-upload_0:2088 [retry.py:__call__():172] Retry attempt failed:
Traceback (most recent call last):
  File "/Users/a58/anaconda3/envs/llama_factory/lib/python3.10/site-packages/urllib3/connectionpool.py", line 703, in urlopen
    httplib_response = self._make_request(
  File "/Users/a58/anaconda3/envs/llama_factory/lib/python3.10/site-packages/urllib3/connectionpool.py", line 386, in _make_request
    self._validate_conn(conn)
  File "/Users/a58/anaconda3/envs/llama_factory/lib/python3.10/site-packages/urllib3/connectionpool.py", line 1042, in _validate_conn
    conn.connect()
  File "/Users/a58/anaconda3/envs/llama_factory/lib/python3.10/site-packages/urllib3/connection.py", line 419, in connect
    self.sock = ssl_wrap_socket(
  File "/Users/a58/anaconda3/envs/llama_factory/lib/python3.10/site-packages/urllib3/util/ssl_.py", line 449, in ssl_wrap_socket
    ssl_sock = _ssl_wrap_socket_impl(
  File "/Users/a58/anaconda3/envs/llama_factory/lib/python3.10/site-packages/urllib3/util/ssl_.py", line 493, in _ssl_wrap_socket_impl
    return ssl_context.wrap_socket(sock, server_hostname=server_hostname)
  File "/Users/a58/anaconda3/envs/llama_factory/lib/python3.10/ssl.py", line 513, in wrap_socket
    return self.sslsocket_class._create(
  File "/Users/a58/anaconda3/envs/llama_factory/lib/python3.10/ssl.py", line 1104, in _create
    self.do_handshake()
  File "/Users/a58/anaconda3/envs/llama_factory/lib/python3.10/ssl.py", line 1375, in do_handshake
    self._sslobj.do_handshake()
ConnectionResetError: [Errno 54] Connection reset by peer

During handling of the above exception, another exception occurred:

Traceback (most recent call last):
  File "/Users/a58/anaconda3/envs/llama_factory/lib/python3.10/site-packages/requests/adapters.py", line 486, in send
    resp = conn.urlopen(
  File "/Users/a58/anaconda3/envs/llama_factory/lib/python3.10/site-packages/urllib3/connectionpool.py", line 787, in urlopen
    retries = retries.increment(
  File "/Users/a58/anaconda3/envs/llama_factory/lib/python3.10/site-packages/urllib3/util/retry.py", line 550, in increment
    raise six.reraise(type(error), error, _stacktrace)
  File "/Users/a58/anaconda3/envs/llama_factory/lib/python3.10/site-packages/urllib3/packages/six.py", line 769, in reraise
    raise value.with_traceback(tb)
  File "/Users/a58/anaconda3/envs/llama_factory/lib/python3.10/site-packages/urllib3/connectionpool.py", line 703, in urlopen
    httplib_response = self._make_request(
  File "/Users/a58/anaconda3/envs/llama_factory/lib/python3.10/site-packages/urllib3/connectionpool.py", line 386, in _make_request
    self._validate_conn(conn)
  File "/Users/a58/anaconda3/envs/llama_factory/lib/python3.10/site-packages/urllib3/connectionpool.py", line 1042, in _validate_conn
    conn.connect()
  File "/Users/a58/anaconda3/envs/llama_factory/lib/python3.10/site-packages/urllib3/connection.py", line 419, in connect
    self.sock = ssl_wrap_socket(
  File "/Users/a58/anaconda3/envs/llama_factory/lib/python3.10/site-packages/urllib3/util/ssl_.py", line 449, in ssl_wrap_socket
    ssl_sock = _ssl_wrap_socket_impl(
  File "/Users/a58/anaconda3/envs/llama_factory/lib/python3.10/site-packages/urllib3/util/ssl_.py", line 493, in _ssl_wrap_socket_impl
    return ssl_context.wrap_socket(sock, server_hostname=server_hostname)
  File "/Users/a58/anaconda3/envs/llama_factory/lib/python3.10/ssl.py", line 513, in wrap_socket
    return self.sslsocket_class._create(
  File "/Users/a58/anaconda3/envs/llama_factory/lib/python3.10/ssl.py", line 1104, in _create
    self.do_handshake()
  File "/Users/a58/anaconda3/envs/llama_factory/lib/python3.10/ssl.py", line 1375, in do_handshake
    self._sslobj.do_handshake()
urllib3.exceptions.ProtocolError: ('Connection aborted.', ConnectionResetError(54, 'Connection reset by peer'))

During handling of the above exception, another exception occurred:

Traceback (most recent call last):
  File "/Users/a58/anaconda3/envs/llama_factory/lib/python3.10/site-packages/wandb/sdk/internal/internal_api.py", line 2760, in upload_file
    response = self._upload_file_session.put(
  File "/Users/a58/anaconda3/envs/llama_factory/lib/python3.10/site-packages/requests/sessions.py", line 649, in put
    return self.request("PUT", url, data=data, **kwargs)
  File "/Users/a58/anaconda3/envs/llama_factory/lib/python3.10/site-packages/requests/sessions.py", line 589, in request
    resp = self.send(prep, **send_kwargs)
  File "/Users/a58/anaconda3/envs/llama_factory/lib/python3.10/site-packages/requests/sessions.py", line 703, in send
    r = adapter.send(request, **kwargs)
  File "/Users/a58/anaconda3/envs/llama_factory/lib/python3.10/site-packages/requests/adapters.py", line 501, in send
    raise ConnectionError(err, request=request)
requests.exceptions.ConnectionError: ('Connection aborted.', ConnectionResetError(54, 'Connection reset by peer'))

During handling of the above exception, another exception occurred:

Traceback (most recent call last):
  File "/Users/a58/anaconda3/envs/llama_factory/lib/python3.10/site-packages/wandb/sdk/lib/retry.py", line 131, in __call__
    result = self._call_fn(*args, **kwargs)
  File "/Users/a58/anaconda3/envs/llama_factory/lib/python3.10/site-packages/wandb/sdk/internal/internal_api.py", line 2791, in upload_file
    raise _e.with_traceback(sys.exc_info()[2])
  File "/Users/a58/anaconda3/envs/llama_factory/lib/python3.10/site-packages/wandb/sdk/internal/internal_api.py", line 2760, in upload_file
    response = self._upload_file_session.put(
  File "/Users/a58/anaconda3/envs/llama_factory/lib/python3.10/site-packages/requests/sessions.py", line 649, in put
    return self.request("PUT", url, data=data, **kwargs)
  File "/Users/a58/anaconda3/envs/llama_factory/lib/python3.10/site-packages/requests/sessions.py", line 589, in request
    resp = self.send(prep, **send_kwargs)
  File "/Users/a58/anaconda3/envs/llama_factory/lib/python3.10/site-packages/requests/sessions.py", line 703, in send
    r = adapter.send(request, **kwargs)
  File "/Users/a58/anaconda3/envs/llama_factory/lib/python3.10/site-packages/requests/adapters.py", line 501, in send
    raise ConnectionError(err, request=request)
wandb.sdk.lib.retry.TransientError: None
2024-04-14 18:33:47,708 ERROR   wandb-upload_0:2088 [internal_api.py:upload_file():2767] upload_file exception https://storage.googleapis.com/wandb-production.appspot.com/darren_qing/Moe_finetuning/fa4vztml/config.yaml?Expires=1713177219&GoogleAccessId=gorilla-files-url-signer-man%40wandb-production.iam.gserviceaccount.com&Signature=Vkmzp9B5uWxH%2BSlAaEicUuY7%2Ft6B3mY7BY3zVzzFSlq95BAEGkgPS6nMk%2FVS8rb8MwgaZRaRu6TBXR%2BBMyBKlCytqun9DpmwILPwkS3fDlpl6cvaNDuic9m89oBGFfxk%2Fb3924nGxVHPUUsEQbsXKwl%2FHICdqwl2iIL4ag8Ycxl%2BNnJjC01yler8QmEpfzluZ3hz9DvggbKVYsW3LcuJtW2c1OSgXzANfqqQWl0X3u%2FbUXjR%2FO31tT60Zozwaj27GaL27%2BiKyLmbu50kZZb3USD92ViJQGENX5Byo8D1N18XgHqHUjsIRIwLZlESmVu7P2ehfLxCohGZ3X64eJ8DJA%3D%3D: ('Connection aborted.', ConnectionResetError(54, 'Connection reset by peer'))
2024-04-14 18:33:47,709 ERROR   wandb-upload_0:2088 [internal_api.py:upload_file():2769] upload_file request headers: {'User-Agent': 'python-requests/2.31.0', 'Accept-Encoding': 'gzip, deflate, br', 'Accept': '*/*', 'Connection': 'keep-alive', 'Content-Length': '500'}
2024-04-14 18:33:47,709 ERROR   wandb-upload_0:2088 [internal_api.py:upload_file():2771] upload_file response body: 
2024-04-14 18:33:56,007 ERROR   wandb-upload_0:2088 [internal_api.py:upload_file():2767] upload_file exception https://storage.googleapis.com/wandb-production.appspot.com/darren_qing/Moe_finetuning/fa4vztml/config.yaml?Expires=1713177219&GoogleAccessId=gorilla-files-url-signer-man%40wandb-production.iam.gserviceaccount.com&Signature=Vkmzp9B5uWxH%2BSlAaEicUuY7%2Ft6B3mY7BY3zVzzFSlq95BAEGkgPS6nMk%2FVS8rb8MwgaZRaRu6TBXR%2BBMyBKlCytqun9DpmwILPwkS3fDlpl6cvaNDuic9m89oBGFfxk%2Fb3924nGxVHPUUsEQbsXKwl%2FHICdqwl2iIL4ag8Ycxl%2BNnJjC01yler8QmEpfzluZ3hz9DvggbKVYsW3LcuJtW2c1OSgXzANfqqQWl0X3u%2FbUXjR%2FO31tT60Zozwaj27GaL27%2BiKyLmbu50kZZb3USD92ViJQGENX5Byo8D1N18XgHqHUjsIRIwLZlESmVu7P2ehfLxCohGZ3X64eJ8DJA%3D%3D: ('Connection aborted.', ConnectionResetError(54, 'Connection reset by peer'))
2024-04-14 18:33:56,007 ERROR   wandb-upload_0:2088 [internal_api.py:upload_file():2769] upload_file request headers: {'User-Agent': 'python-requests/2.31.0', 'Accept-Encoding': 'gzip, deflate, br', 'Accept': '*/*', 'Connection': 'keep-alive', 'Content-Length': '500'}
2024-04-14 18:33:56,007 ERROR   wandb-upload_0:2088 [internal_api.py:upload_file():2771] upload_file response body: 
2024-04-14 18:34:12,844 ERROR   wandb-upload_0:2088 [internal_api.py:upload_file():2767] upload_file exception https://storage.googleapis.com/wandb-production.appspot.com/darren_qing/Moe_finetuning/fa4vztml/config.yaml?Expires=1713177219&GoogleAccessId=gorilla-files-url-signer-man%40wandb-production.iam.gserviceaccount.com&Signature=Vkmzp9B5uWxH%2BSlAaEicUuY7%2Ft6B3mY7BY3zVzzFSlq95BAEGkgPS6nMk%2FVS8rb8MwgaZRaRu6TBXR%2BBMyBKlCytqun9DpmwILPwkS3fDlpl6cvaNDuic9m89oBGFfxk%2Fb3924nGxVHPUUsEQbsXKwl%2FHICdqwl2iIL4ag8Ycxl%2BNnJjC01yler8QmEpfzluZ3hz9DvggbKVYsW3LcuJtW2c1OSgXzANfqqQWl0X3u%2FbUXjR%2FO31tT60Zozwaj27GaL27%2BiKyLmbu50kZZb3USD92ViJQGENX5Byo8D1N18XgHqHUjsIRIwLZlESmVu7P2ehfLxCohGZ3X64eJ8DJA%3D%3D: ('Connection aborted.', ConnectionResetError(54, 'Connection reset by peer'))
2024-04-14 18:34:12,844 ERROR   wandb-upload_0:2088 [internal_api.py:upload_file():2769] upload_file request headers: {'User-Agent': 'python-requests/2.31.0', 'Accept-Encoding': 'gzip, deflate, br', 'Accept': '*/*', 'Connection': 'keep-alive', 'Content-Length': '500'}
2024-04-14 18:34:12,844 ERROR   wandb-upload_0:2088 [internal_api.py:upload_file():2771] upload_file response body: 
2024-04-14 18:34:48,162 ERROR   wandb-upload_0:2088 [internal_api.py:upload_file():2767] upload_file exception https://storage.googleapis.com/wandb-production.appspot.com/darren_qing/Moe_finetuning/fa4vztml/config.yaml?Expires=1713177219&GoogleAccessId=gorilla-files-url-signer-man%40wandb-production.iam.gserviceaccount.com&Signature=Vkmzp9B5uWxH%2BSlAaEicUuY7%2Ft6B3mY7BY3zVzzFSlq95BAEGkgPS6nMk%2FVS8rb8MwgaZRaRu6TBXR%2BBMyBKlCytqun9DpmwILPwkS3fDlpl6cvaNDuic9m89oBGFfxk%2Fb3924nGxVHPUUsEQbsXKwl%2FHICdqwl2iIL4ag8Ycxl%2BNnJjC01yler8QmEpfzluZ3hz9DvggbKVYsW3LcuJtW2c1OSgXzANfqqQWl0X3u%2FbUXjR%2FO31tT60Zozwaj27GaL27%2BiKyLmbu50kZZb3USD92ViJQGENX5Byo8D1N18XgHqHUjsIRIwLZlESmVu7P2ehfLxCohGZ3X64eJ8DJA%3D%3D: ('Connection aborted.', ConnectionResetError(54, 'Connection reset by peer'))
2024-04-14 18:34:48,162 ERROR   wandb-upload_0:2088 [internal_api.py:upload_file():2769] upload_file request headers: {'User-Agent': 'python-requests/2.31.0', 'Accept-Encoding': 'gzip, deflate, br', 'Accept': '*/*', 'Connection': 'keep-alive', 'Content-Length': '500'}
2024-04-14 18:34:48,163 ERROR   wandb-upload_0:2088 [internal_api.py:upload_file():2771] upload_file response body: 
2024-04-14 18:36:05,713 ERROR   wandb-upload_0:2088 [internal_api.py:upload_file():2767] upload_file exception https://storage.googleapis.com/wandb-production.appspot.com/darren_qing/Moe_finetuning/fa4vztml/config.yaml?Expires=1713177219&GoogleAccessId=gorilla-files-url-signer-man%40wandb-production.iam.gserviceaccount.com&Signature=Vkmzp9B5uWxH%2BSlAaEicUuY7%2Ft6B3mY7BY3zVzzFSlq95BAEGkgPS6nMk%2FVS8rb8MwgaZRaRu6TBXR%2BBMyBKlCytqun9DpmwILPwkS3fDlpl6cvaNDuic9m89oBGFfxk%2Fb3924nGxVHPUUsEQbsXKwl%2FHICdqwl2iIL4ag8Ycxl%2BNnJjC01yler8QmEpfzluZ3hz9DvggbKVYsW3LcuJtW2c1OSgXzANfqqQWl0X3u%2FbUXjR%2FO31tT60Zozwaj27GaL27%2BiKyLmbu50kZZb3USD92ViJQGENX5Byo8D1N18XgHqHUjsIRIwLZlESmVu7P2ehfLxCohGZ3X64eJ8DJA%3D%3D: ('Connection aborted.', ConnectionResetError(54, 'Connection reset by peer'))
2024-04-14 18:36:05,718 ERROR   wandb-upload_0:2088 [internal_api.py:upload_file():2769] upload_file request headers: {'User-Agent': 'python-requests/2.31.0', 'Accept-Encoding': 'gzip, deflate, br', 'Accept': '*/*', 'Connection': 'keep-alive', 'Content-Length': '500'}
2024-04-14 18:36:05,718 ERROR   wandb-upload_0:2088 [internal_api.py:upload_file():2771] upload_file response body: 
2024-04-14 18:38:29,826 ERROR   wandb-upload_0:2088 [internal_api.py:upload_file():2767] upload_file exception https://storage.googleapis.com/wandb-production.appspot.com/darren_qing/Moe_finetuning/fa4vztml/config.yaml?Expires=1713177219&GoogleAccessId=gorilla-files-url-signer-man%40wandb-production.iam.gserviceaccount.com&Signature=Vkmzp9B5uWxH%2BSlAaEicUuY7%2Ft6B3mY7BY3zVzzFSlq95BAEGkgPS6nMk%2FVS8rb8MwgaZRaRu6TBXR%2BBMyBKlCytqun9DpmwILPwkS3fDlpl6cvaNDuic9m89oBGFfxk%2Fb3924nGxVHPUUsEQbsXKwl%2FHICdqwl2iIL4ag8Ycxl%2BNnJjC01yler8QmEpfzluZ3hz9DvggbKVYsW3LcuJtW2c1OSgXzANfqqQWl0X3u%2FbUXjR%2FO31tT60Zozwaj27GaL27%2BiKyLmbu50kZZb3USD92ViJQGENX5Byo8D1N18XgHqHUjsIRIwLZlESmVu7P2ehfLxCohGZ3X64eJ8DJA%3D%3D: ('Connection aborted.', ConnectionResetError(54, 'Connection reset by peer'))
2024-04-14 18:38:29,827 ERROR   wandb-upload_0:2088 [internal_api.py:upload_file():2769] upload_file request headers: {'User-Agent': 'python-requests/2.31.0', 'Accept-Encoding': 'gzip, deflate, br', 'Accept': '*/*', 'Connection': 'keep-alive', 'Content-Length': '500'}
2024-04-14 18:38:29,827 ERROR   wandb-upload_0:2088 [internal_api.py:upload_file():2771] upload_file response body: 
2024-04-14 18:43:06,690 ERROR   wandb-upload_0:2088 [internal_api.py:upload_file():2767] upload_file exception https://storage.googleapis.com/wandb-production.appspot.com/darren_qing/Moe_finetuning/fa4vztml/config.yaml?Expires=1713177219&GoogleAccessId=gorilla-files-url-signer-man%40wandb-production.iam.gserviceaccount.com&Signature=Vkmzp9B5uWxH%2BSlAaEicUuY7%2Ft6B3mY7BY3zVzzFSlq95BAEGkgPS6nMk%2FVS8rb8MwgaZRaRu6TBXR%2BBMyBKlCytqun9DpmwILPwkS3fDlpl6cvaNDuic9m89oBGFfxk%2Fb3924nGxVHPUUsEQbsXKwl%2FHICdqwl2iIL4ag8Ycxl%2BNnJjC01yler8QmEpfzluZ3hz9DvggbKVYsW3LcuJtW2c1OSgXzANfqqQWl0X3u%2FbUXjR%2FO31tT60Zozwaj27GaL27%2BiKyLmbu50kZZb3USD92ViJQGENX5Byo8D1N18XgHqHUjsIRIwLZlESmVu7P2ehfLxCohGZ3X64eJ8DJA%3D%3D: ('Connection aborted.', ConnectionResetError(54, 'Connection reset by peer'))
2024-04-14 18:43:06,691 ERROR   wandb-upload_0:2088 [internal_api.py:upload_file():2769] upload_file request headers: {'User-Agent': 'python-requests/2.31.0', 'Accept-Encoding': 'gzip, deflate, br', 'Accept': '*/*', 'Connection': 'keep-alive', 'Content-Length': '500'}
2024-04-14 18:43:06,692 ERROR   wandb-upload_0:2088 [internal_api.py:upload_file():2771] upload_file response body: 
2024-04-14 18:48:32,553 ERROR   wandb-upload_0:2088 [internal_api.py:upload_file():2767] upload_file exception https://storage.googleapis.com/wandb-production.appspot.com/darren_qing/Moe_finetuning/fa4vztml/config.yaml?Expires=1713177219&GoogleAccessId=gorilla-files-url-signer-man%40wandb-production.iam.gserviceaccount.com&Signature=Vkmzp9B5uWxH%2BSlAaEicUuY7%2Ft6B3mY7BY3zVzzFSlq95BAEGkgPS6nMk%2FVS8rb8MwgaZRaRu6TBXR%2BBMyBKlCytqun9DpmwILPwkS3fDlpl6cvaNDuic9m89oBGFfxk%2Fb3924nGxVHPUUsEQbsXKwl%2FHICdqwl2iIL4ag8Ycxl%2BNnJjC01yler8QmEpfzluZ3hz9DvggbKVYsW3LcuJtW2c1OSgXzANfqqQWl0X3u%2FbUXjR%2FO31tT60Zozwaj27GaL27%2BiKyLmbu50kZZb3USD92ViJQGENX5Byo8D1N18XgHqHUjsIRIwLZlESmVu7P2ehfLxCohGZ3X64eJ8DJA%3D%3D: ('Connection aborted.', ConnectionResetError(54, 'Connection reset by peer'))
2024-04-14 18:48:32,555 ERROR   wandb-upload_0:2088 [internal_api.py:upload_file():2769] upload_file request headers: {'User-Agent': 'python-requests/2.31.0', 'Accept-Encoding': 'gzip, deflate, br', 'Accept': '*/*', 'Connection': 'keep-alive', 'Content-Length': '500'}
2024-04-14 18:48:32,555 ERROR   wandb-upload_0:2088 [internal_api.py:upload_file():2771] upload_file response body: 
2024-04-14 18:53:50,681 ERROR   wandb-upload_0:2088 [internal_api.py:upload_file():2767] upload_file exception https://storage.googleapis.com/wandb-production.appspot.com/darren_qing/Moe_finetuning/fa4vztml/config.yaml?Expires=1713177219&GoogleAccessId=gorilla-files-url-signer-man%40wandb-production.iam.gserviceaccount.com&Signature=Vkmzp9B5uWxH%2BSlAaEicUuY7%2Ft6B3mY7BY3zVzzFSlq95BAEGkgPS6nMk%2FVS8rb8MwgaZRaRu6TBXR%2BBMyBKlCytqun9DpmwILPwkS3fDlpl6cvaNDuic9m89oBGFfxk%2Fb3924nGxVHPUUsEQbsXKwl%2FHICdqwl2iIL4ag8Ycxl%2BNnJjC01yler8QmEpfzluZ3hz9DvggbKVYsW3LcuJtW2c1OSgXzANfqqQWl0X3u%2FbUXjR%2FO31tT60Zozwaj27GaL27%2BiKyLmbu50kZZb3USD92ViJQGENX5Byo8D1N18XgHqHUjsIRIwLZlESmVu7P2ehfLxCohGZ3X64eJ8DJA%3D%3D: ('Connection aborted.', ConnectionResetError(54, 'Connection reset by peer'))
2024-04-14 18:53:50,684 ERROR   wandb-upload_0:2088 [internal_api.py:upload_file():2769] upload_file request headers: {'User-Agent': 'python-requests/2.31.0', 'Accept-Encoding': 'gzip, deflate, br', 'Accept': '*/*', 'Connection': 'keep-alive', 'Content-Length': '500'}
2024-04-14 18:53:50,685 ERROR   wandb-upload_0:2088 [internal_api.py:upload_file():2771] upload_file response body: 
2024-04-14 18:59:59,097 ERROR   wandb-upload_0:2088 [internal_api.py:upload_file():2767] upload_file exception https://storage.googleapis.com/wandb-production.appspot.com/darren_qing/Moe_finetuning/fa4vztml/config.yaml?Expires=1713177219&GoogleAccessId=gorilla-files-url-signer-man%40wandb-production.iam.gserviceaccount.com&Signature=Vkmzp9B5uWxH%2BSlAaEicUuY7%2Ft6B3mY7BY3zVzzFSlq95BAEGkgPS6nMk%2FVS8rb8MwgaZRaRu6TBXR%2BBMyBKlCytqun9DpmwILPwkS3fDlpl6cvaNDuic9m89oBGFfxk%2Fb3924nGxVHPUUsEQbsXKwl%2FHICdqwl2iIL4ag8Ycxl%2BNnJjC01yler8QmEpfzluZ3hz9DvggbKVYsW3LcuJtW2c1OSgXzANfqqQWl0X3u%2FbUXjR%2FO31tT60Zozwaj27GaL27%2BiKyLmbu50kZZb3USD92ViJQGENX5Byo8D1N18XgHqHUjsIRIwLZlESmVu7P2ehfLxCohGZ3X64eJ8DJA%3D%3D: ('Connection aborted.', ConnectionResetError(54, 'Connection reset by peer'))
2024-04-14 18:59:59,097 ERROR   wandb-upload_0:2088 [internal_api.py:upload_file():2769] upload_file request headers: {'User-Agent': 'python-requests/2.31.0', 'Accept-Encoding': 'gzip, deflate, br', 'Accept': '*/*', 'Connection': 'keep-alive', 'Content-Length': '500'}
2024-04-14 18:59:59,098 ERROR   wandb-upload_0:2088 [internal_api.py:upload_file():2771] upload_file response body: 
2024-04-14 19:05:40,483 ERROR   wandb-upload_0:2088 [internal_api.py:upload_file():2767] upload_file exception https://storage.googleapis.com/wandb-production.appspot.com/darren_qing/Moe_finetuning/fa4vztml/config.yaml?Expires=1713177219&GoogleAccessId=gorilla-files-url-signer-man%40wandb-production.iam.gserviceaccount.com&Signature=Vkmzp9B5uWxH%2BSlAaEicUuY7%2Ft6B3mY7BY3zVzzFSlq95BAEGkgPS6nMk%2FVS8rb8MwgaZRaRu6TBXR%2BBMyBKlCytqun9DpmwILPwkS3fDlpl6cvaNDuic9m89oBGFfxk%2Fb3924nGxVHPUUsEQbsXKwl%2FHICdqwl2iIL4ag8Ycxl%2BNnJjC01yler8QmEpfzluZ3hz9DvggbKVYsW3LcuJtW2c1OSgXzANfqqQWl0X3u%2FbUXjR%2FO31tT60Zozwaj27GaL27%2BiKyLmbu50kZZb3USD92ViJQGENX5Byo8D1N18XgHqHUjsIRIwLZlESmVu7P2ehfLxCohGZ3X64eJ8DJA%3D%3D: ('Connection aborted.', ConnectionResetError(54, 'Connection reset by peer'))
2024-04-14 19:05:40,484 ERROR   wandb-upload_0:2088 [internal_api.py:upload_file():2769] upload_file request headers: {'User-Agent': 'python-requests/2.31.0', 'Accept-Encoding': 'gzip, deflate, br', 'Accept': '*/*', 'Connection': 'keep-alive', 'Content-Length': '500'}
2024-04-14 19:05:40,484 ERROR   wandb-upload_0:2088 [internal_api.py:upload_file():2771] upload_file response body: 
2024-04-14 19:10:59,922 ERROR   wandb-upload_0:2088 [internal_api.py:upload_file():2767] upload_file exception https://storage.googleapis.com/wandb-production.appspot.com/darren_qing/Moe_finetuning/fa4vztml/config.yaml?Expires=1713177219&GoogleAccessId=gorilla-files-url-signer-man%40wandb-production.iam.gserviceaccount.com&Signature=Vkmzp9B5uWxH%2BSlAaEicUuY7%2Ft6B3mY7BY3zVzzFSlq95BAEGkgPS6nMk%2FVS8rb8MwgaZRaRu6TBXR%2BBMyBKlCytqun9DpmwILPwkS3fDlpl6cvaNDuic9m89oBGFfxk%2Fb3924nGxVHPUUsEQbsXKwl%2FHICdqwl2iIL4ag8Ycxl%2BNnJjC01yler8QmEpfzluZ3hz9DvggbKVYsW3LcuJtW2c1OSgXzANfqqQWl0X3u%2FbUXjR%2FO31tT60Zozwaj27GaL27%2BiKyLmbu50kZZb3USD92ViJQGENX5Byo8D1N18XgHqHUjsIRIwLZlESmVu7P2ehfLxCohGZ3X64eJ8DJA%3D%3D: ('Connection aborted.', ConnectionResetError(54, 'Connection reset by peer'))
2024-04-14 19:10:59,924 ERROR   wandb-upload_0:2088 [internal_api.py:upload_file():2769] upload_file request headers: {'User-Agent': 'python-requests/2.31.0', 'Accept-Encoding': 'gzip, deflate, br', 'Accept': '*/*', 'Connection': 'keep-alive', 'Content-Length': '500'}
2024-04-14 19:10:59,924 ERROR   wandb-upload_0:2088 [internal_api.py:upload_file():2771] upload_file response body: 
2024-04-14 19:16:18,217 ERROR   wandb-upload_0:2088 [internal_api.py:upload_file():2767] upload_file exception https://storage.googleapis.com/wandb-production.appspot.com/darren_qing/Moe_finetuning/fa4vztml/config.yaml?Expires=1713177219&GoogleAccessId=gorilla-files-url-signer-man%40wandb-production.iam.gserviceaccount.com&Signature=Vkmzp9B5uWxH%2BSlAaEicUuY7%2Ft6B3mY7BY3zVzzFSlq95BAEGkgPS6nMk%2FVS8rb8MwgaZRaRu6TBXR%2BBMyBKlCytqun9DpmwILPwkS3fDlpl6cvaNDuic9m89oBGFfxk%2Fb3924nGxVHPUUsEQbsXKwl%2FHICdqwl2iIL4ag8Ycxl%2BNnJjC01yler8QmEpfzluZ3hz9DvggbKVYsW3LcuJtW2c1OSgXzANfqqQWl0X3u%2FbUXjR%2FO31tT60Zozwaj27GaL27%2BiKyLmbu50kZZb3USD92ViJQGENX5Byo8D1N18XgHqHUjsIRIwLZlESmVu7P2ehfLxCohGZ3X64eJ8DJA%3D%3D: ('Connection aborted.', ConnectionResetError(54, 'Connection reset by peer'))
2024-04-14 19:16:18,217 ERROR   wandb-upload_0:2088 [internal_api.py:upload_file():2769] upload_file request headers: {'User-Agent': 'python-requests/2.31.0', 'Accept-Encoding': 'gzip, deflate, br', 'Accept': '*/*', 'Connection': 'keep-alive', 'Content-Length': '500'}
2024-04-14 19:16:18,217 ERROR   wandb-upload_0:2088 [internal_api.py:upload_file():2771] upload_file response body: 
2024-04-14 19:22:28,005 ERROR   wandb-upload_0:2088 [internal_api.py:upload_file():2767] upload_file exception https://storage.googleapis.com/wandb-production.appspot.com/darren_qing/Moe_finetuning/fa4vztml/config.yaml?Expires=1713177219&GoogleAccessId=gorilla-files-url-signer-man%40wandb-production.iam.gserviceaccount.com&Signature=Vkmzp9B5uWxH%2BSlAaEicUuY7%2Ft6B3mY7BY3zVzzFSlq95BAEGkgPS6nMk%2FVS8rb8MwgaZRaRu6TBXR%2BBMyBKlCytqun9DpmwILPwkS3fDlpl6cvaNDuic9m89oBGFfxk%2Fb3924nGxVHPUUsEQbsXKwl%2FHICdqwl2iIL4ag8Ycxl%2BNnJjC01yler8QmEpfzluZ3hz9DvggbKVYsW3LcuJtW2c1OSgXzANfqqQWl0X3u%2FbUXjR%2FO31tT60Zozwaj27GaL27%2BiKyLmbu50kZZb3USD92ViJQGENX5Byo8D1N18XgHqHUjsIRIwLZlESmVu7P2ehfLxCohGZ3X64eJ8DJA%3D%3D: ('Connection aborted.', ConnectionResetError(54, 'Connection reset by peer'))
2024-04-14 19:22:28,005 ERROR   wandb-upload_0:2088 [internal_api.py:upload_file():2769] upload_file request headers: {'User-Agent': 'python-requests/2.31.0', 'Accept-Encoding': 'gzip, deflate, br', 'Accept': '*/*', 'Connection': 'keep-alive', 'Content-Length': '500'}
2024-04-14 19:22:28,005 ERROR   wandb-upload_0:2088 [internal_api.py:upload_file():2771] upload_file response body: 
2024-04-14 19:27:54,310 ERROR   wandb-upload_0:2088 [internal_api.py:upload_file():2767] upload_file exception https://storage.googleapis.com/wandb-production.appspot.com/darren_qing/Moe_finetuning/fa4vztml/config.yaml?Expires=1713177219&GoogleAccessId=gorilla-files-url-signer-man%40wandb-production.iam.gserviceaccount.com&Signature=Vkmzp9B5uWxH%2BSlAaEicUuY7%2Ft6B3mY7BY3zVzzFSlq95BAEGkgPS6nMk%2FVS8rb8MwgaZRaRu6TBXR%2BBMyBKlCytqun9DpmwILPwkS3fDlpl6cvaNDuic9m89oBGFfxk%2Fb3924nGxVHPUUsEQbsXKwl%2FHICdqwl2iIL4ag8Ycxl%2BNnJjC01yler8QmEpfzluZ3hz9DvggbKVYsW3LcuJtW2c1OSgXzANfqqQWl0X3u%2FbUXjR%2FO31tT60Zozwaj27GaL27%2BiKyLmbu50kZZb3USD92ViJQGENX5Byo8D1N18XgHqHUjsIRIwLZlESmVu7P2ehfLxCohGZ3X64eJ8DJA%3D%3D: ('Connection aborted.', ConnectionResetError(54, 'Connection reset by peer'))
2024-04-14 19:27:54,311 ERROR   wandb-upload_0:2088 [internal_api.py:upload_file():2769] upload_file request headers: {'User-Agent': 'python-requests/2.31.0', 'Accept-Encoding': 'gzip, deflate, br', 'Accept': '*/*', 'Connection': 'keep-alive', 'Content-Length': '500'}
2024-04-14 19:27:54,311 ERROR   wandb-upload_0:2088 [internal_api.py:upload_file():2771] upload_file response body: 
2024-04-14 19:32:57,170 ERROR   wandb-upload_0:2088 [internal_api.py:upload_file():2767] upload_file exception https://storage.googleapis.com/wandb-production.appspot.com/darren_qing/Moe_finetuning/fa4vztml/config.yaml?Expires=1713177219&GoogleAccessId=gorilla-files-url-signer-man%40wandb-production.iam.gserviceaccount.com&Signature=Vkmzp9B5uWxH%2BSlAaEicUuY7%2Ft6B3mY7BY3zVzzFSlq95BAEGkgPS6nMk%2FVS8rb8MwgaZRaRu6TBXR%2BBMyBKlCytqun9DpmwILPwkS3fDlpl6cvaNDuic9m89oBGFfxk%2Fb3924nGxVHPUUsEQbsXKwl%2FHICdqwl2iIL4ag8Ycxl%2BNnJjC01yler8QmEpfzluZ3hz9DvggbKVYsW3LcuJtW2c1OSgXzANfqqQWl0X3u%2FbUXjR%2FO31tT60Zozwaj27GaL27%2BiKyLmbu50kZZb3USD92ViJQGENX5Byo8D1N18XgHqHUjsIRIwLZlESmVu7P2ehfLxCohGZ3X64eJ8DJA%3D%3D: ('Connection aborted.', ConnectionResetError(54, 'Connection reset by peer'))
2024-04-14 19:32:57,170 ERROR   wandb-upload_0:2088 [internal_api.py:upload_file():2769] upload_file request headers: {'User-Agent': 'python-requests/2.31.0', 'Accept-Encoding': 'gzip, deflate, br', 'Accept': '*/*', 'Connection': 'keep-alive', 'Content-Length': '500'}
2024-04-14 19:32:57,170 ERROR   wandb-upload_0:2088 [internal_api.py:upload_file():2771] upload_file response body: 
2024-04-14 19:38:48,307 ERROR   wandb-upload_0:2088 [internal_api.py:upload_file():2767] upload_file exception https://storage.googleapis.com/wandb-production.appspot.com/darren_qing/Moe_finetuning/fa4vztml/config.yaml?Expires=1713177219&GoogleAccessId=gorilla-files-url-signer-man%40wandb-production.iam.gserviceaccount.com&Signature=Vkmzp9B5uWxH%2BSlAaEicUuY7%2Ft6B3mY7BY3zVzzFSlq95BAEGkgPS6nMk%2FVS8rb8MwgaZRaRu6TBXR%2BBMyBKlCytqun9DpmwILPwkS3fDlpl6cvaNDuic9m89oBGFfxk%2Fb3924nGxVHPUUsEQbsXKwl%2FHICdqwl2iIL4ag8Ycxl%2BNnJjC01yler8QmEpfzluZ3hz9DvggbKVYsW3LcuJtW2c1OSgXzANfqqQWl0X3u%2FbUXjR%2FO31tT60Zozwaj27GaL27%2BiKyLmbu50kZZb3USD92ViJQGENX5Byo8D1N18XgHqHUjsIRIwLZlESmVu7P2ehfLxCohGZ3X64eJ8DJA%3D%3D: ('Connection aborted.', ConnectionResetError(54, 'Connection reset by peer'))
2024-04-14 19:38:48,308 ERROR   wandb-upload_0:2088 [internal_api.py:upload_file():2769] upload_file request headers: {'User-Agent': 'python-requests/2.31.0', 'Accept-Encoding': 'gzip, deflate, br', 'Accept': '*/*', 'Connection': 'keep-alive', 'Content-Length': '500'}
2024-04-14 19:38:48,308 ERROR   wandb-upload_0:2088 [internal_api.py:upload_file():2771] upload_file response body: 
2024-04-14 19:44:33,317 ERROR   wandb-upload_0:2088 [internal_api.py:upload_file():2767] upload_file exception https://storage.googleapis.com/wandb-production.appspot.com/darren_qing/Moe_finetuning/fa4vztml/config.yaml?Expires=1713177219&GoogleAccessId=gorilla-files-url-signer-man%40wandb-production.iam.gserviceaccount.com&Signature=Vkmzp9B5uWxH%2BSlAaEicUuY7%2Ft6B3mY7BY3zVzzFSlq95BAEGkgPS6nMk%2FVS8rb8MwgaZRaRu6TBXR%2BBMyBKlCytqun9DpmwILPwkS3fDlpl6cvaNDuic9m89oBGFfxk%2Fb3924nGxVHPUUsEQbsXKwl%2FHICdqwl2iIL4ag8Ycxl%2BNnJjC01yler8QmEpfzluZ3hz9DvggbKVYsW3LcuJtW2c1OSgXzANfqqQWl0X3u%2FbUXjR%2FO31tT60Zozwaj27GaL27%2BiKyLmbu50kZZb3USD92ViJQGENX5Byo8D1N18XgHqHUjsIRIwLZlESmVu7P2ehfLxCohGZ3X64eJ8DJA%3D%3D: ('Connection aborted.', ConnectionResetError(54, 'Connection reset by peer'))
2024-04-14 19:44:33,317 ERROR   wandb-upload_0:2088 [internal_api.py:upload_file():2769] upload_file request headers: {'User-Agent': 'python-requests/2.31.0', 'Accept-Encoding': 'gzip, deflate, br', 'Accept': '*/*', 'Connection': 'keep-alive', 'Content-Length': '500'}
2024-04-14 19:44:33,318 ERROR   wandb-upload_0:2088 [internal_api.py:upload_file():2771] upload_file response body: 
2024-04-14 19:50:41,725 ERROR   wandb-upload_0:2088 [internal_api.py:upload_file():2767] upload_file exception https://storage.googleapis.com/wandb-production.appspot.com/darren_qing/Moe_finetuning/fa4vztml/config.yaml?Expires=1713177219&GoogleAccessId=gorilla-files-url-signer-man%40wandb-production.iam.gserviceaccount.com&Signature=Vkmzp9B5uWxH%2BSlAaEicUuY7%2Ft6B3mY7BY3zVzzFSlq95BAEGkgPS6nMk%2FVS8rb8MwgaZRaRu6TBXR%2BBMyBKlCytqun9DpmwILPwkS3fDlpl6cvaNDuic9m89oBGFfxk%2Fb3924nGxVHPUUsEQbsXKwl%2FHICdqwl2iIL4ag8Ycxl%2BNnJjC01yler8QmEpfzluZ3hz9DvggbKVYsW3LcuJtW2c1OSgXzANfqqQWl0X3u%2FbUXjR%2FO31tT60Zozwaj27GaL27%2BiKyLmbu50kZZb3USD92ViJQGENX5Byo8D1N18XgHqHUjsIRIwLZlESmVu7P2ehfLxCohGZ3X64eJ8DJA%3D%3D: ('Connection aborted.', ConnectionResetError(54, 'Connection reset by peer'))
2024-04-14 19:50:41,725 ERROR   wandb-upload_0:2088 [internal_api.py:upload_file():2769] upload_file request headers: {'User-Agent': 'python-requests/2.31.0', 'Accept-Encoding': 'gzip, deflate, br', 'Accept': '*/*', 'Connection': 'keep-alive', 'Content-Length': '500'}
2024-04-14 19:50:41,726 ERROR   wandb-upload_0:2088 [internal_api.py:upload_file():2771] upload_file response body: 
2024-04-14 19:56:06,547 ERROR   wandb-upload_0:2088 [internal_api.py:upload_file():2767] upload_file exception https://storage.googleapis.com/wandb-production.appspot.com/darren_qing/Moe_finetuning/fa4vztml/config.yaml?Expires=1713177219&GoogleAccessId=gorilla-files-url-signer-man%40wandb-production.iam.gserviceaccount.com&Signature=Vkmzp9B5uWxH%2BSlAaEicUuY7%2Ft6B3mY7BY3zVzzFSlq95BAEGkgPS6nMk%2FVS8rb8MwgaZRaRu6TBXR%2BBMyBKlCytqun9DpmwILPwkS3fDlpl6cvaNDuic9m89oBGFfxk%2Fb3924nGxVHPUUsEQbsXKwl%2FHICdqwl2iIL4ag8Ycxl%2BNnJjC01yler8QmEpfzluZ3hz9DvggbKVYsW3LcuJtW2c1OSgXzANfqqQWl0X3u%2FbUXjR%2FO31tT60Zozwaj27GaL27%2BiKyLmbu50kZZb3USD92ViJQGENX5Byo8D1N18XgHqHUjsIRIwLZlESmVu7P2ehfLxCohGZ3X64eJ8DJA%3D%3D: ('Connection aborted.', ConnectionResetError(54, 'Connection reset by peer'))
2024-04-14 19:56:06,547 ERROR   wandb-upload_0:2088 [internal_api.py:upload_file():2769] upload_file request headers: {'User-Agent': 'python-requests/2.31.0', 'Accept-Encoding': 'gzip, deflate, br', 'Accept': '*/*', 'Connection': 'keep-alive', 'Content-Length': '500'}
2024-04-14 19:56:06,547 ERROR   wandb-upload_0:2088 [internal_api.py:upload_file():2771] upload_file response body: 
2024-04-14 20:01:59,123 ERROR   wandb-upload_0:2088 [internal_api.py:upload_file():2767] upload_file exception https://storage.googleapis.com/wandb-production.appspot.com/darren_qing/Moe_finetuning/fa4vztml/config.yaml?Expires=1713177219&GoogleAccessId=gorilla-files-url-signer-man%40wandb-production.iam.gserviceaccount.com&Signature=Vkmzp9B5uWxH%2BSlAaEicUuY7%2Ft6B3mY7BY3zVzzFSlq95BAEGkgPS6nMk%2FVS8rb8MwgaZRaRu6TBXR%2BBMyBKlCytqun9DpmwILPwkS3fDlpl6cvaNDuic9m89oBGFfxk%2Fb3924nGxVHPUUsEQbsXKwl%2FHICdqwl2iIL4ag8Ycxl%2BNnJjC01yler8QmEpfzluZ3hz9DvggbKVYsW3LcuJtW2c1OSgXzANfqqQWl0X3u%2FbUXjR%2FO31tT60Zozwaj27GaL27%2BiKyLmbu50kZZb3USD92ViJQGENX5Byo8D1N18XgHqHUjsIRIwLZlESmVu7P2ehfLxCohGZ3X64eJ8DJA%3D%3D: ('Connection aborted.', ConnectionResetError(54, 'Connection reset by peer'))
2024-04-14 20:01:59,123 ERROR   wandb-upload_0:2088 [internal_api.py:upload_file():2769] upload_file request headers: {'User-Agent': 'python-requests/2.31.0', 'Accept-Encoding': 'gzip, deflate, br', 'Accept': '*/*', 'Connection': 'keep-alive', 'Content-Length': '500'}
2024-04-14 20:01:59,124 ERROR   wandb-upload_0:2088 [internal_api.py:upload_file():2771] upload_file response body: 
2024-04-14 20:07:35,832 ERROR   wandb-upload_0:2088 [internal_api.py:upload_file():2767] upload_file exception https://storage.googleapis.com/wandb-production.appspot.com/darren_qing/Moe_finetuning/fa4vztml/config.yaml?Expires=1713177219&GoogleAccessId=gorilla-files-url-signer-man%40wandb-production.iam.gserviceaccount.com&Signature=Vkmzp9B5uWxH%2BSlAaEicUuY7%2Ft6B3mY7BY3zVzzFSlq95BAEGkgPS6nMk%2FVS8rb8MwgaZRaRu6TBXR%2BBMyBKlCytqun9DpmwILPwkS3fDlpl6cvaNDuic9m89oBGFfxk%2Fb3924nGxVHPUUsEQbsXKwl%2FHICdqwl2iIL4ag8Ycxl%2BNnJjC01yler8QmEpfzluZ3hz9DvggbKVYsW3LcuJtW2c1OSgXzANfqqQWl0X3u%2FbUXjR%2FO31tT60Zozwaj27GaL27%2BiKyLmbu50kZZb3USD92ViJQGENX5Byo8D1N18XgHqHUjsIRIwLZlESmVu7P2ehfLxCohGZ3X64eJ8DJA%3D%3D: ('Connection aborted.', ConnectionResetError(54, 'Connection reset by peer'))
2024-04-14 20:07:35,832 ERROR   wandb-upload_0:2088 [internal_api.py:upload_file():2769] upload_file request headers: {'User-Agent': 'python-requests/2.31.0', 'Accept-Encoding': 'gzip, deflate, br', 'Accept': '*/*', 'Connection': 'keep-alive', 'Content-Length': '500'}
2024-04-14 20:07:35,833 ERROR   wandb-upload_0:2088 [internal_api.py:upload_file():2771] upload_file response body: 
2024-04-14 21:16:03,522 INFO    wandb-upload_0:2088 [upload_job.py:push():131] Uploaded file /Users/a58/Downloads/MoE_Train/finetune/wandb/run-20240414_183336-fa4vztml/files/config.yaml
2024-04-14 21:16:04,184 INFO    SenderThread:2088 [file_stream.py:finish():614] file stream finish called
2024-04-14 21:33:57,545 WARNING FileStreamThread:2088 [file_stream.py:request_with_retry():687] requests_with_retry encountered retryable exception: HTTPSConnectionPool(host='api.wandb.ai', port=443): Read timed out. (read timeout=180.0). func: functools.partial(<bound method Session.post of <requests.sessions.Session object at 0x13c1dbdc0>>, timeout=180.0), args: ('https://api.wandb.ai/files/darren_qing/Moe_finetuning/fa4vztml/file_stream',), kwargs: {'json': {'complete': False, 'failed': False, 'dropped': 0, 'uploaded': []}}
2024-04-14 21:34:00,497 INFO    SenderThread:2088 [file_stream.py:finish():618] file stream finish is done
