2024-04-24 17:32:41,576 INFO    StreamThr :40667 [internal.py:wandb_internal():86] W&B internal server running at pid: 40667, started at: 2024-04-24 17:32:41.575090
2024-04-24 17:32:41,579 DEBUG   HandlerThread:40667 [handler.py:handle_request():146] handle_request: status
2024-04-24 17:32:41,584 INFO    WriterThread:40667 [datastore.py:open_for_write():87] open: /Users/a58/Downloads/MoE_Train/finetune/wandb/run-20240424_173241-eqj6jv3s/run-eqj6jv3s.wandb
2024-04-24 17:32:41,585 DEBUG   SenderThread:40667 [sender.py:send():379] send: header
2024-04-24 17:32:41,632 DEBUG   SenderThread:40667 [sender.py:send():379] send: run
2024-04-24 17:32:42,376 INFO    SenderThread:40667 [dir_watcher.py:__init__():211] watching files in: /Users/a58/Downloads/MoE_Train/finetune/wandb/run-20240424_173241-eqj6jv3s/files
2024-04-24 17:32:42,377 INFO    SenderThread:40667 [sender.py:_start_run_threads():1124] run started: eqj6jv3s with start time 1713951161.576557
2024-04-24 17:32:42,405 DEBUG   HandlerThread:40667 [handler.py:handle_request():146] handle_request: check_version
2024-04-24 17:32:42,405 DEBUG   SenderThread:40667 [sender.py:send_request():406] send_request: check_version
2024-04-24 17:32:42,689 DEBUG   HandlerThread:40667 [handler.py:handle_request():146] handle_request: run_start
2024-04-24 17:32:42,697 DEBUG   HandlerThread:40667 [system_info.py:__init__():26] System info init
2024-04-24 17:32:42,698 DEBUG   HandlerThread:40667 [system_info.py:__init__():41] System info init done
2024-04-24 17:32:42,698 INFO    HandlerThread:40667 [system_monitor.py:start():194] Starting system monitor
2024-04-24 17:32:42,698 INFO    HandlerThread:40667 [system_monitor.py:probe():214] Collecting system info
2024-04-24 17:32:42,699 INFO    SystemMonitor:40667 [system_monitor.py:_start():158] Starting system asset monitoring threads
2024-04-24 17:32:42,699 DEBUG   HandlerThread:40667 [system_info.py:probe():150] Probing system
2024-04-24 17:32:42,701 INFO    SystemMonitor:40667 [interfaces.py:start():190] Started cpu monitoring
2024-04-24 17:32:42,702 INFO    SystemMonitor:40667 [interfaces.py:start():190] Started disk monitoring
2024-04-24 17:32:42,708 INFO    SystemMonitor:40667 [interfaces.py:start():190] Started gpuapple monitoring
2024-04-24 17:32:42,711 INFO    SystemMonitor:40667 [interfaces.py:start():190] Started memory monitoring
2024-04-24 17:32:42,713 INFO    SystemMonitor:40667 [interfaces.py:start():190] Started network monitoring
2024-04-24 17:32:42,719 DEBUG   HandlerThread:40667 [system_info.py:_probe_git():135] Probing git
2024-04-24 17:32:42,751 DEBUG   HandlerThread:40667 [system_info.py:_probe_git():143] Probing git done
2024-04-24 17:32:42,752 DEBUG   HandlerThread:40667 [system_info.py:probe():198] Probing system done
2024-04-24 17:32:42,752 DEBUG   HandlerThread:40667 [system_monitor.py:probe():223] {'os': 'macOS-14.2.1-arm64-arm-64bit', 'python': '3.10.13', 'heartbeatAt': '2024-04-24T09:32:42.700040', 'startedAt': '2024-04-24T09:32:41.567393', 'docker': None, 'cuda': None, 'args': ('--model_name_or_path', '/Users/a58/Downloads/pretrain_model/Qwen/Qwen1.5-0.5B-Chat', '--do_train', 'True', '--per_device_train_batch_size', '1', '--gradient_accumulation_steps', '1', '--learning_rate', '5e-5', '--weight_decay', '0', '--max_grad_norm', '1.0', '--num_train_epochs', '1.0', '--block_size', '32', '--train_file', '/Users/a58/Downloads/my_test/data/data_sft/renting_data_train_7000_improved_prompting3.json', '--output_dir', '/Users/a58/Downloads/MoE_Train/outputs', '--overwrite_output_dir', '--logging_dir', '/Users/a58/Downloads/MoE_Train/outputs', '--save_strategy', 'epoch', '--save_total_limit', '1', '--logging_strategy', 'steps', '--logging_steps', '1', '--report_to', 'wandb', '--trust_remote_code', 'True', '--template', 'llama3', '--q_lora', 'False', '--use_lora', 'True', '--lora_r', '8', '--lora_alpha', '32', '--lora_dropout', '0.05', '--lora_target_modules', 'q_proj', 'v_proj', 'k_proj', 'o_proj', 'gate_proj', 'down_proj', 'up_proj'), 'state': 'running', 'program': '/Users/a58/Downloads/MoE_Train/finetune/run.py', 'codePathLocal': 'run.py', 'codePath': 'finetune/run.py', 'git': {'remote': 'https://github.com/Darrenzeng/MoE_Train.git', 'commit': 'f1f43f83852171df6bd535b6c39de48dca03c558'}, 'email': 'zengyufei@58.com', 'root': '/Users/a58/Downloads/MoE_Train', 'host': '58deMacBook-Pro-2.local', 'username': 'a58', 'executable': '/Users/a58/anaconda3/envs/llama_factory/bin/python', 'cpu_count': 8, 'cpu_count_logical': 8, 'disk': {'/': {'total': 228.27386474609375, 'used': 13.368824005126953}}, 'gpuapple': {'type': 'arm', 'vendor': 'Apple'}, 'memory': {'total': 16.0}}
2024-04-24 17:32:42,752 INFO    HandlerThread:40667 [system_monitor.py:probe():224] Finished collecting system info
2024-04-24 17:32:42,752 INFO    HandlerThread:40667 [system_monitor.py:probe():227] Publishing system info
2024-04-24 17:32:42,752 DEBUG   HandlerThread:40667 [system_info.py:_save_conda():207] Saving list of conda packages installed into the current environment
2024-04-24 17:32:43,381 INFO    Thread-17 :40667 [dir_watcher.py:_on_file_created():271] file/dir created: /Users/a58/Downloads/MoE_Train/finetune/wandb/run-20240424_173241-eqj6jv3s/files/conda-environment.yaml
2024-04-24 17:32:45,939 DEBUG   HandlerThread:40667 [system_info.py:_save_conda():222] Saving conda packages done
2024-04-24 17:32:45,940 INFO    HandlerThread:40667 [system_monitor.py:probe():229] Finished publishing system info
2024-04-24 17:32:45,943 DEBUG   SenderThread:40667 [sender.py:send():379] send: files
2024-04-24 17:32:45,943 INFO    SenderThread:40667 [sender.py:_save_file():1390] saving file wandb-metadata.json with policy now
2024-04-24 17:32:46,385 DEBUG   HandlerThread:40667 [handler.py:handle_request():146] handle_request: python_packages
2024-04-24 17:32:46,385 DEBUG   SenderThread:40667 [sender.py:send_request():406] send_request: python_packages
2024-04-24 17:32:46,386 DEBUG   HandlerThread:40667 [handler.py:handle_request():146] handle_request: stop_status
2024-04-24 17:32:46,386 DEBUG   SenderThread:40667 [sender.py:send_request():406] send_request: stop_status
2024-04-24 17:32:46,388 DEBUG   HandlerThread:40667 [handler.py:handle_request():146] handle_request: internal_messages
2024-04-24 17:32:46,393 INFO    Thread-17 :40667 [dir_watcher.py:_on_file_modified():288] file/dir modified: /Users/a58/Downloads/MoE_Train/finetune/wandb/run-20240424_173241-eqj6jv3s/files/conda-environment.yaml
2024-04-24 17:32:46,393 INFO    Thread-17 :40667 [dir_watcher.py:_on_file_created():271] file/dir created: /Users/a58/Downloads/MoE_Train/finetune/wandb/run-20240424_173241-eqj6jv3s/files/wandb-metadata.json
2024-04-24 17:32:46,393 INFO    Thread-17 :40667 [dir_watcher.py:_on_file_created():271] file/dir created: /Users/a58/Downloads/MoE_Train/finetune/wandb/run-20240424_173241-eqj6jv3s/files/requirements.txt
2024-04-24 17:32:46,525 ERROR   wandb-upload_0:40667 [internal_api.py:upload_file():2767] upload_file exception https://storage.googleapis.com/wandb-production.appspot.com/darren_qing/Moe_finetuning/eqj6jv3s/wandb-metadata.json?Expires=1714037566&GoogleAccessId=gorilla-files-url-signer-man%40wandb-production.iam.gserviceaccount.com&Signature=QenUieFYHmkHYE75zginXCasU%2FtglFn9tqQAdUj4FbbBINipYA9tkPFfOvShFrMxh5tW1p0%2FZ5j1SsjEwdl4D2hk1ZdfexJ1%2F2ZYk68ukw9AHKSMBeW1JU6SFmIoQxVSy9JJraKprmxhx%2FDPCZC5bjbvbNPb47i%2BidGYKa8bgP%2Bul3txIkOlQyPZEOlRxij34JBOJegZgijdsCatpUkqH%2BAAwX%2F9A%2BoufenQZSQBd1v1FKilFFwxs8TpjWfmhz9ORxCd744GlRKjUvLLtJWgaE43%2BsLfW4PLu5u19uwokwF9Q8yAlAoWWL2e9%2BsCkIFvN5JztEbU7oxHFlhDOwRCYw%3D%3D: ('Connection aborted.', ConnectionResetError(54, 'Connection reset by peer'))
2024-04-24 17:32:46,525 ERROR   wandb-upload_0:40667 [internal_api.py:upload_file():2769] upload_file request headers: {'User-Agent': 'python-requests/2.31.0', 'Accept-Encoding': 'gzip, deflate, br', 'Accept': '*/*', 'Connection': 'keep-alive', 'Content-Length': '2451'}
2024-04-24 17:32:46,526 ERROR   wandb-upload_0:40667 [internal_api.py:upload_file():2771] upload_file response body: 
2024-04-24 17:32:46,771 DEBUG   SenderThread:40667 [sender.py:send():379] send: telemetry
2024-04-24 17:32:46,772 DEBUG   HandlerThread:40667 [handler.py:handle_request():146] handle_request: status_report
2024-04-24 17:32:46,772 DEBUG   SenderThread:40667 [sender.py:send():379] send: config
2024-04-24 17:32:46,775 DEBUG   SenderThread:40667 [sender.py:send():379] send: metric
2024-04-24 17:32:46,776 DEBUG   SenderThread:40667 [sender.py:send():379] send: telemetry
2024-04-24 17:32:46,776 DEBUG   SenderThread:40667 [sender.py:send():379] send: metric
2024-04-24 17:32:46,776 WARNING SenderThread:40667 [sender.py:send_metric():1341] Seen metric with glob (shouldn't happen)
2024-04-24 17:32:46,776 DEBUG   SenderThread:40667 [sender.py:send():379] send: telemetry
2024-04-24 17:32:47,282 DEBUG   SenderThread:40667 [sender.py:send():379] send: exit
2024-04-24 17:32:47,289 INFO    SenderThread:40667 [sender.py:send_exit():586] handling exit code: 255
2024-04-24 17:32:47,296 INFO    SenderThread:40667 [sender.py:send_exit():588] handling runtime: 4
2024-04-24 17:32:47,326 INFO    SenderThread:40667 [sender.py:_save_file():1390] saving file wandb-summary.json with policy end
2024-04-24 17:32:47,335 INFO    SenderThread:40667 [sender.py:send_exit():594] send defer
2024-04-24 17:32:47,336 DEBUG   HandlerThread:40667 [handler.py:handle_request():146] handle_request: defer
2024-04-24 17:32:47,336 INFO    HandlerThread:40667 [handler.py:handle_request_defer():172] handle defer: 0
2024-04-24 17:32:47,337 DEBUG   SenderThread:40667 [sender.py:send_request():406] send_request: defer
2024-04-24 17:32:47,337 INFO    SenderThread:40667 [sender.py:send_request_defer():610] handle sender defer: 0
2024-04-24 17:32:47,337 INFO    SenderThread:40667 [sender.py:transition_state():614] send defer: 1
2024-04-24 17:32:47,337 DEBUG   HandlerThread:40667 [handler.py:handle_request():146] handle_request: defer
2024-04-24 17:32:47,337 INFO    HandlerThread:40667 [handler.py:handle_request_defer():172] handle defer: 1
2024-04-24 17:32:47,338 DEBUG   SenderThread:40667 [sender.py:send_request():406] send_request: defer
2024-04-24 17:32:47,338 INFO    SenderThread:40667 [sender.py:send_request_defer():610] handle sender defer: 1
2024-04-24 17:32:47,338 INFO    SenderThread:40667 [sender.py:transition_state():614] send defer: 2
2024-04-24 17:32:47,338 DEBUG   HandlerThread:40667 [handler.py:handle_request():146] handle_request: defer
2024-04-24 17:32:47,338 INFO    HandlerThread:40667 [handler.py:handle_request_defer():172] handle defer: 2
2024-04-24 17:32:47,338 INFO    HandlerThread:40667 [system_monitor.py:finish():203] Stopping system monitor
2024-04-24 17:32:47,339 DEBUG   SystemMonitor:40667 [system_monitor.py:_start():172] Starting system metrics aggregation loop
2024-04-24 17:32:47,339 DEBUG   SystemMonitor:40667 [system_monitor.py:_start():179] Finished system metrics aggregation loop
2024-04-24 17:32:47,339 DEBUG   SystemMonitor:40667 [system_monitor.py:_start():183] Publishing last batch of metrics
2024-04-24 17:32:47,340 INFO    HandlerThread:40667 [interfaces.py:finish():202] Joined cpu monitor
2024-04-24 17:32:47,341 INFO    HandlerThread:40667 [interfaces.py:finish():202] Joined disk monitor
2024-04-24 17:32:47,342 INFO    HandlerThread:40667 [interfaces.py:finish():202] Joined gpuapple monitor
2024-04-24 17:32:47,342 INFO    HandlerThread:40667 [interfaces.py:finish():202] Joined memory monitor
2024-04-24 17:32:47,342 INFO    HandlerThread:40667 [interfaces.py:finish():202] Joined network monitor
2024-04-24 17:32:47,344 DEBUG   SenderThread:40667 [sender.py:send_request():406] send_request: defer
2024-04-24 17:32:47,344 INFO    SenderThread:40667 [sender.py:send_request_defer():610] handle sender defer: 2
2024-04-24 17:32:47,345 INFO    SenderThread:40667 [sender.py:transition_state():614] send defer: 3
2024-04-24 17:32:47,345 DEBUG   SenderThread:40667 [sender.py:send():379] send: telemetry
2024-04-24 17:32:47,345 DEBUG   HandlerThread:40667 [handler.py:handle_request():146] handle_request: defer
2024-04-24 17:32:47,345 DEBUG   SenderThread:40667 [sender.py:send():379] send: stats
2024-04-24 17:32:47,346 INFO    HandlerThread:40667 [handler.py:handle_request_defer():172] handle defer: 3
2024-04-24 17:32:47,347 DEBUG   SenderThread:40667 [sender.py:send_request():406] send_request: defer
2024-04-24 17:32:47,347 INFO    SenderThread:40667 [sender.py:send_request_defer():610] handle sender defer: 3
2024-04-24 17:32:47,347 INFO    SenderThread:40667 [sender.py:transition_state():614] send defer: 4
2024-04-24 17:32:47,347 DEBUG   HandlerThread:40667 [handler.py:handle_request():146] handle_request: defer
2024-04-24 17:32:47,347 INFO    HandlerThread:40667 [handler.py:handle_request_defer():172] handle defer: 4
2024-04-24 17:32:47,347 DEBUG   SenderThread:40667 [sender.py:send_request():406] send_request: defer
2024-04-24 17:32:47,347 INFO    SenderThread:40667 [sender.py:send_request_defer():610] handle sender defer: 4
2024-04-24 17:32:47,347 INFO    SenderThread:40667 [sender.py:transition_state():614] send defer: 5
2024-04-24 17:32:47,347 DEBUG   HandlerThread:40667 [handler.py:handle_request():146] handle_request: defer
2024-04-24 17:32:47,347 INFO    HandlerThread:40667 [handler.py:handle_request_defer():172] handle defer: 5
2024-04-24 17:32:47,348 DEBUG   SenderThread:40667 [sender.py:send():379] send: summary
2024-04-24 17:32:47,349 INFO    SenderThread:40667 [sender.py:_save_file():1390] saving file wandb-summary.json with policy end
2024-04-24 17:32:47,349 DEBUG   SenderThread:40667 [sender.py:send_request():406] send_request: defer
2024-04-24 17:32:47,349 INFO    SenderThread:40667 [sender.py:send_request_defer():610] handle sender defer: 5
2024-04-24 17:32:47,349 INFO    SenderThread:40667 [sender.py:transition_state():614] send defer: 6
2024-04-24 17:32:47,349 DEBUG   HandlerThread:40667 [handler.py:handle_request():146] handle_request: defer
2024-04-24 17:32:47,349 INFO    HandlerThread:40667 [handler.py:handle_request_defer():172] handle defer: 6
2024-04-24 17:32:47,350 DEBUG   SenderThread:40667 [sender.py:send_request():406] send_request: defer
2024-04-24 17:32:47,350 INFO    SenderThread:40667 [sender.py:send_request_defer():610] handle sender defer: 6
2024-04-24 17:32:47,356 DEBUG   HandlerThread:40667 [handler.py:handle_request():146] handle_request: status_report
2024-04-24 17:32:47,397 INFO    Thread-17 :40667 [dir_watcher.py:_on_file_created():271] file/dir created: /Users/a58/Downloads/MoE_Train/finetune/wandb/run-20240424_173241-eqj6jv3s/files/output.log
2024-04-24 17:32:47,397 INFO    Thread-17 :40667 [dir_watcher.py:_on_file_created():271] file/dir created: /Users/a58/Downloads/MoE_Train/finetune/wandb/run-20240424_173241-eqj6jv3s/files/wandb-summary.json
2024-04-24 17:32:47,731 INFO    SenderThread:40667 [sender.py:transition_state():614] send defer: 7
2024-04-24 17:32:47,731 DEBUG   HandlerThread:40667 [handler.py:handle_request():146] handle_request: defer
2024-04-24 17:32:47,732 INFO    HandlerThread:40667 [handler.py:handle_request_defer():172] handle defer: 7
2024-04-24 17:32:47,732 DEBUG   SenderThread:40667 [sender.py:send_request():406] send_request: defer
2024-04-24 17:32:47,732 INFO    SenderThread:40667 [sender.py:send_request_defer():610] handle sender defer: 7
2024-04-24 17:32:47,839 ERROR   wandb-upload_0:40667 [internal_api.py:upload_file():2767] upload_file exception https://storage.googleapis.com/wandb-production.appspot.com/darren_qing/Moe_finetuning/eqj6jv3s/wandb-metadata.json?Expires=1714037566&GoogleAccessId=gorilla-files-url-signer-man%40wandb-production.iam.gserviceaccount.com&Signature=QenUieFYHmkHYE75zginXCasU%2FtglFn9tqQAdUj4FbbBINipYA9tkPFfOvShFrMxh5tW1p0%2FZ5j1SsjEwdl4D2hk1ZdfexJ1%2F2ZYk68ukw9AHKSMBeW1JU6SFmIoQxVSy9JJraKprmxhx%2FDPCZC5bjbvbNPb47i%2BidGYKa8bgP%2Bul3txIkOlQyPZEOlRxij34JBOJegZgijdsCatpUkqH%2BAAwX%2F9A%2BoufenQZSQBd1v1FKilFFwxs8TpjWfmhz9ORxCd744GlRKjUvLLtJWgaE43%2BsLfW4PLu5u19uwokwF9Q8yAlAoWWL2e9%2BsCkIFvN5JztEbU7oxHFlhDOwRCYw%3D%3D: ('Connection aborted.', ConnectionResetError(54, 'Connection reset by peer'))
2024-04-24 17:32:47,839 ERROR   wandb-upload_0:40667 [internal_api.py:upload_file():2769] upload_file request headers: {'User-Agent': 'python-requests/2.31.0', 'Accept-Encoding': 'gzip, deflate, br', 'Accept': '*/*', 'Connection': 'keep-alive', 'Content-Length': '2451'}
2024-04-24 17:32:47,839 ERROR   wandb-upload_0:40667 [internal_api.py:upload_file():2771] upload_file response body: 
2024-04-24 17:32:48,287 DEBUG   HandlerThread:40667 [handler.py:handle_request():146] handle_request: poll_exit
2024-04-24 17:32:48,402 INFO    Thread-17 :40667 [dir_watcher.py:_on_file_modified():288] file/dir modified: /Users/a58/Downloads/MoE_Train/finetune/wandb/run-20240424_173241-eqj6jv3s/files/config.yaml
2024-04-24 17:32:48,800 INFO    SenderThread:40667 [sender.py:transition_state():614] send defer: 8
2024-04-24 17:32:48,801 DEBUG   SenderThread:40667 [sender.py:send_request():406] send_request: poll_exit
2024-04-24 17:32:48,802 DEBUG   HandlerThread:40667 [handler.py:handle_request():146] handle_request: defer
2024-04-24 17:32:48,803 INFO    HandlerThread:40667 [handler.py:handle_request_defer():172] handle defer: 8
2024-04-24 17:32:48,807 DEBUG   SenderThread:40667 [sender.py:send_request():406] send_request: defer
2024-04-24 17:32:48,808 INFO    SenderThread:40667 [sender.py:send_request_defer():610] handle sender defer: 8
2024-04-24 17:32:48,808 INFO    SenderThread:40667 [job_builder.py:build():318] Attempting to build job artifact
2024-04-24 17:32:48,813 INFO    SenderThread:40667 [job_builder.py:_get_source_type():455] is repo sourced job
2024-04-24 17:32:49,293 DEBUG   HandlerThread:40667 [handler.py:handle_request():146] handle_request: poll_exit
2024-04-24 17:32:49,404 INFO    Thread-17 :40667 [dir_watcher.py:_on_file_modified():288] file/dir modified: /Users/a58/Downloads/MoE_Train/finetune/wandb/run-20240424_173241-eqj6jv3s/files/output.log
2024-04-24 17:32:49,834 INFO    SenderThread:40667 [job_builder.py:build():431] adding wandb-job metadata file
2024-04-24 17:32:49,852 INFO    SenderThread:40667 [sender.py:transition_state():614] send defer: 9
2024-04-24 17:32:49,852 DEBUG   SenderThread:40667 [sender.py:send_request():406] send_request: poll_exit
2024-04-24 17:32:49,852 DEBUG   HandlerThread:40667 [handler.py:handle_request():146] handle_request: defer
2024-04-24 17:32:49,852 INFO    HandlerThread:40667 [handler.py:handle_request_defer():172] handle defer: 9
2024-04-24 17:32:49,853 DEBUG   SenderThread:40667 [sender.py:send():379] send: artifact
2024-04-24 17:32:50,300 DEBUG   HandlerThread:40667 [handler.py:handle_request():146] handle_request: poll_exit
2024-04-24 17:32:50,522 ERROR   wandb-upload_0:40667 [internal_api.py:upload_file():2767] upload_file exception https://storage.googleapis.com/wandb-production.appspot.com/darren_qing/Moe_finetuning/eqj6jv3s/wandb-metadata.json?Expires=1714037566&GoogleAccessId=gorilla-files-url-signer-man%40wandb-production.iam.gserviceaccount.com&Signature=QenUieFYHmkHYE75zginXCasU%2FtglFn9tqQAdUj4FbbBINipYA9tkPFfOvShFrMxh5tW1p0%2FZ5j1SsjEwdl4D2hk1ZdfexJ1%2F2ZYk68ukw9AHKSMBeW1JU6SFmIoQxVSy9JJraKprmxhx%2FDPCZC5bjbvbNPb47i%2BidGYKa8bgP%2Bul3txIkOlQyPZEOlRxij34JBOJegZgijdsCatpUkqH%2BAAwX%2F9A%2BoufenQZSQBd1v1FKilFFwxs8TpjWfmhz9ORxCd744GlRKjUvLLtJWgaE43%2BsLfW4PLu5u19uwokwF9Q8yAlAoWWL2e9%2BsCkIFvN5JztEbU7oxHFlhDOwRCYw%3D%3D: ('Connection aborted.', ConnectionResetError(54, 'Connection reset by peer'))
2024-04-24 17:32:50,522 ERROR   wandb-upload_0:40667 [internal_api.py:upload_file():2769] upload_file request headers: {'User-Agent': 'python-requests/2.31.0', 'Accept-Encoding': 'gzip, deflate, br', 'Accept': '*/*', 'Connection': 'keep-alive', 'Content-Length': '2451'}
2024-04-24 17:32:50,522 ERROR   wandb-upload_0:40667 [internal_api.py:upload_file():2771] upload_file response body: 
2024-04-24 17:32:50,522 INFO    wandb-upload_0:40667 [retry.py:__call__():172] Retry attempt failed:
Traceback (most recent call last):
  File "/Users/a58/anaconda3/envs/llama_factory/lib/python3.10/site-packages/urllib3/connectionpool.py", line 703, in urlopen
    httplib_response = self._make_request(
  File "/Users/a58/anaconda3/envs/llama_factory/lib/python3.10/site-packages/urllib3/connectionpool.py", line 386, in _make_request
    self._validate_conn(conn)
  File "/Users/a58/anaconda3/envs/llama_factory/lib/python3.10/site-packages/urllib3/connectionpool.py", line 1042, in _validate_conn
    conn.connect()
  File "/Users/a58/anaconda3/envs/llama_factory/lib/python3.10/site-packages/urllib3/connection.py", line 419, in connect
    self.sock = ssl_wrap_socket(
  File "/Users/a58/anaconda3/envs/llama_factory/lib/python3.10/site-packages/urllib3/util/ssl_.py", line 449, in ssl_wrap_socket
    ssl_sock = _ssl_wrap_socket_impl(
  File "/Users/a58/anaconda3/envs/llama_factory/lib/python3.10/site-packages/urllib3/util/ssl_.py", line 493, in _ssl_wrap_socket_impl
    return ssl_context.wrap_socket(sock, server_hostname=server_hostname)
  File "/Users/a58/anaconda3/envs/llama_factory/lib/python3.10/ssl.py", line 513, in wrap_socket
    return self.sslsocket_class._create(
  File "/Users/a58/anaconda3/envs/llama_factory/lib/python3.10/ssl.py", line 1104, in _create
    self.do_handshake()
  File "/Users/a58/anaconda3/envs/llama_factory/lib/python3.10/ssl.py", line 1375, in do_handshake
    self._sslobj.do_handshake()
ConnectionResetError: [Errno 54] Connection reset by peer

During handling of the above exception, another exception occurred:

Traceback (most recent call last):
  File "/Users/a58/anaconda3/envs/llama_factory/lib/python3.10/site-packages/requests/adapters.py", line 486, in send
    resp = conn.urlopen(
  File "/Users/a58/anaconda3/envs/llama_factory/lib/python3.10/site-packages/urllib3/connectionpool.py", line 787, in urlopen
    retries = retries.increment(
  File "/Users/a58/anaconda3/envs/llama_factory/lib/python3.10/site-packages/urllib3/util/retry.py", line 550, in increment
    raise six.reraise(type(error), error, _stacktrace)
  File "/Users/a58/anaconda3/envs/llama_factory/lib/python3.10/site-packages/urllib3/packages/six.py", line 769, in reraise
    raise value.with_traceback(tb)
  File "/Users/a58/anaconda3/envs/llama_factory/lib/python3.10/site-packages/urllib3/connectionpool.py", line 703, in urlopen
    httplib_response = self._make_request(
  File "/Users/a58/anaconda3/envs/llama_factory/lib/python3.10/site-packages/urllib3/connectionpool.py", line 386, in _make_request
    self._validate_conn(conn)
  File "/Users/a58/anaconda3/envs/llama_factory/lib/python3.10/site-packages/urllib3/connectionpool.py", line 1042, in _validate_conn
    conn.connect()
  File "/Users/a58/anaconda3/envs/llama_factory/lib/python3.10/site-packages/urllib3/connection.py", line 419, in connect
    self.sock = ssl_wrap_socket(
  File "/Users/a58/anaconda3/envs/llama_factory/lib/python3.10/site-packages/urllib3/util/ssl_.py", line 449, in ssl_wrap_socket
    ssl_sock = _ssl_wrap_socket_impl(
  File "/Users/a58/anaconda3/envs/llama_factory/lib/python3.10/site-packages/urllib3/util/ssl_.py", line 493, in _ssl_wrap_socket_impl
    return ssl_context.wrap_socket(sock, server_hostname=server_hostname)
  File "/Users/a58/anaconda3/envs/llama_factory/lib/python3.10/ssl.py", line 513, in wrap_socket
    return self.sslsocket_class._create(
  File "/Users/a58/anaconda3/envs/llama_factory/lib/python3.10/ssl.py", line 1104, in _create
    self.do_handshake()
  File "/Users/a58/anaconda3/envs/llama_factory/lib/python3.10/ssl.py", line 1375, in do_handshake
    self._sslobj.do_handshake()
urllib3.exceptions.ProtocolError: ('Connection aborted.', ConnectionResetError(54, 'Connection reset by peer'))

During handling of the above exception, another exception occurred:

Traceback (most recent call last):
  File "/Users/a58/anaconda3/envs/llama_factory/lib/python3.10/site-packages/wandb/sdk/internal/internal_api.py", line 2760, in upload_file
    response = self._upload_file_session.put(
  File "/Users/a58/anaconda3/envs/llama_factory/lib/python3.10/site-packages/requests/sessions.py", line 649, in put
    return self.request("PUT", url, data=data, **kwargs)
  File "/Users/a58/anaconda3/envs/llama_factory/lib/python3.10/site-packages/requests/sessions.py", line 589, in request
    resp = self.send(prep, **send_kwargs)
  File "/Users/a58/anaconda3/envs/llama_factory/lib/python3.10/site-packages/requests/sessions.py", line 703, in send
    r = adapter.send(request, **kwargs)
  File "/Users/a58/anaconda3/envs/llama_factory/lib/python3.10/site-packages/requests/adapters.py", line 501, in send
    raise ConnectionError(err, request=request)
requests.exceptions.ConnectionError: ('Connection aborted.', ConnectionResetError(54, 'Connection reset by peer'))

During handling of the above exception, another exception occurred:

Traceback (most recent call last):
  File "/Users/a58/anaconda3/envs/llama_factory/lib/python3.10/site-packages/wandb/sdk/lib/retry.py", line 131, in __call__
    result = self._call_fn(*args, **kwargs)
  File "/Users/a58/anaconda3/envs/llama_factory/lib/python3.10/site-packages/wandb/sdk/internal/internal_api.py", line 2791, in upload_file
    raise _e.with_traceback(sys.exc_info()[2])
  File "/Users/a58/anaconda3/envs/llama_factory/lib/python3.10/site-packages/wandb/sdk/internal/internal_api.py", line 2760, in upload_file
    response = self._upload_file_session.put(
  File "/Users/a58/anaconda3/envs/llama_factory/lib/python3.10/site-packages/requests/sessions.py", line 649, in put
    return self.request("PUT", url, data=data, **kwargs)
  File "/Users/a58/anaconda3/envs/llama_factory/lib/python3.10/site-packages/requests/sessions.py", line 589, in request
    resp = self.send(prep, **send_kwargs)
  File "/Users/a58/anaconda3/envs/llama_factory/lib/python3.10/site-packages/requests/sessions.py", line 703, in send
    r = adapter.send(request, **kwargs)
  File "/Users/a58/anaconda3/envs/llama_factory/lib/python3.10/site-packages/requests/adapters.py", line 501, in send
    raise ConnectionError(err, request=request)
wandb.sdk.lib.retry.TransientError: None
2024-04-24 17:32:50,612 WARNING StreamThr :40667 [internal.py:is_dead():414] Internal process exiting, parent pid 40589 disappeared
2024-04-24 17:32:50,612 ERROR   StreamThr :40667 [internal.py:wandb_internal():152] Internal process shutdown.
2024-04-24 17:32:51,303 INFO    HandlerThread:40667 [handler.py:finish():866] shutting down handler
2024-04-24 17:32:51,305 INFO    WriterThread:40667 [datastore.py:close():296] close: /Users/a58/Downloads/MoE_Train/finetune/wandb/run-20240424_173241-eqj6jv3s/run-eqj6jv3s.wandb
2024-04-24 17:32:51,938 INFO    wandb-upload_1:40667 [upload_job.py:push():86] Skipped uploading /Users/a58/Library/Application Support/wandb/artifacts/staging/tmpcfmxi25_
2024-04-24 17:32:55,211 ERROR   wandb-upload_0:40667 [internal_api.py:upload_file():2767] upload_file exception https://storage.googleapis.com/wandb-production.appspot.com/darren_qing/Moe_finetuning/eqj6jv3s/wandb-metadata.json?Expires=1714037566&GoogleAccessId=gorilla-files-url-signer-man%40wandb-production.iam.gserviceaccount.com&Signature=QenUieFYHmkHYE75zginXCasU%2FtglFn9tqQAdUj4FbbBINipYA9tkPFfOvShFrMxh5tW1p0%2FZ5j1SsjEwdl4D2hk1ZdfexJ1%2F2ZYk68ukw9AHKSMBeW1JU6SFmIoQxVSy9JJraKprmxhx%2FDPCZC5bjbvbNPb47i%2BidGYKa8bgP%2Bul3txIkOlQyPZEOlRxij34JBOJegZgijdsCatpUkqH%2BAAwX%2F9A%2BoufenQZSQBd1v1FKilFFwxs8TpjWfmhz9ORxCd744GlRKjUvLLtJWgaE43%2BsLfW4PLu5u19uwokwF9Q8yAlAoWWL2e9%2BsCkIFvN5JztEbU7oxHFlhDOwRCYw%3D%3D: ('Connection aborted.', ConnectionResetError(54, 'Connection reset by peer'))
2024-04-24 17:32:55,211 ERROR   wandb-upload_0:40667 [internal_api.py:upload_file():2769] upload_file request headers: {'User-Agent': 'python-requests/2.31.0', 'Accept-Encoding': 'gzip, deflate, br', 'Accept': '*/*', 'Connection': 'keep-alive', 'Content-Length': '2451'}
2024-04-24 17:32:55,211 ERROR   wandb-upload_0:40667 [internal_api.py:upload_file():2771] upload_file response body: 
2024-04-24 17:33:02,339 ERROR   wandb-upload_2:40667 [internal_api.py:upload_file():2767] upload_file exception https://storage.googleapis.com/wandb-artifacts-prod/wandb_artifacts/162462141/808153240/f67dea45d1a3ee48492235110f50cd3c?Expires=1714037571&GoogleAccessId=gorilla-files-url-signer-man%40wandb-production.iam.gserviceaccount.com&Signature=dz7GB3pUmrkR6gRXsMeSr8ofzsonG2XkgOOl2Uko%2BmtXvABoUbitEG8NUZqpdN4HZvN9LoVA4V4kWCdQmDVpp5pvZcEBhKrXrc5qt1caDrg6T8qRZSdFmoRcNWYFSjYNtACB7EDmqX8NKaQl5RG%2BXReAGVkQEzo8mvHkHEiFT2P3x9BI168c3MzlO9y7XoWLBOc1DN2FR9D8fRqU0lM4Az8fg%2BMXfrtr%2ByGIBjeJG3ImLJtmtbGT74A%2F%2Bm32RcNErK3cUQC5EU4I2G8MWWJTati6P7%2BcJ4nYFrxLJCfEI8qx5bR7OX3bhycjoGxGdgI67zy01r3507sEZX7RjKJ3fg%3D%3D: HTTPSConnectionPool(host='storage.googleapis.com', port=443): Max retries exceeded with url: /wandb-artifacts-prod/wandb_artifacts/162462141/808153240/f67dea45d1a3ee48492235110f50cd3c?Expires=1714037571&GoogleAccessId=gorilla-files-url-signer-man%40wandb-production.iam.gserviceaccount.com&Signature=dz7GB3pUmrkR6gRXsMeSr8ofzsonG2XkgOOl2Uko%2BmtXvABoUbitEG8NUZqpdN4HZvN9LoVA4V4kWCdQmDVpp5pvZcEBhKrXrc5qt1caDrg6T8qRZSdFmoRcNWYFSjYNtACB7EDmqX8NKaQl5RG%2BXReAGVkQEzo8mvHkHEiFT2P3x9BI168c3MzlO9y7XoWLBOc1DN2FR9D8fRqU0lM4Az8fg%2BMXfrtr%2ByGIBjeJG3ImLJtmtbGT74A%2F%2Bm32RcNErK3cUQC5EU4I2G8MWWJTati6P7%2BcJ4nYFrxLJCfEI8qx5bR7OX3bhycjoGxGdgI67zy01r3507sEZX7RjKJ3fg%3D%3D (Caused by SSLError(SSLEOFError(8, '[SSL: UNEXPECTED_EOF_WHILE_READING] EOF occurred in violation of protocol (_ssl.c:1007)')))
2024-04-24 17:33:02,340 ERROR   wandb-upload_2:40667 [internal_api.py:upload_file():2769] upload_file request headers: {'User-Agent': 'python-requests/2.31.0', 'Accept-Encoding': 'gzip, deflate, br', 'Accept': '*/*', 'Connection': 'keep-alive', 'Content-MD5': '9n3qRdGj7khJIjURD1DNPA==', 'Content-Type': 'application/json', 'Content-Length': '23218'}
2024-04-24 17:33:02,340 ERROR   wandb-upload_2:40667 [internal_api.py:upload_file():2771] upload_file response body: 
2024-04-24 17:33:03,607 ERROR   wandb-upload_2:40667 [internal_api.py:upload_file():2767] upload_file exception https://storage.googleapis.com/wandb-artifacts-prod/wandb_artifacts/162462141/808153240/f67dea45d1a3ee48492235110f50cd3c?Expires=1714037571&GoogleAccessId=gorilla-files-url-signer-man%40wandb-production.iam.gserviceaccount.com&Signature=dz7GB3pUmrkR6gRXsMeSr8ofzsonG2XkgOOl2Uko%2BmtXvABoUbitEG8NUZqpdN4HZvN9LoVA4V4kWCdQmDVpp5pvZcEBhKrXrc5qt1caDrg6T8qRZSdFmoRcNWYFSjYNtACB7EDmqX8NKaQl5RG%2BXReAGVkQEzo8mvHkHEiFT2P3x9BI168c3MzlO9y7XoWLBOc1DN2FR9D8fRqU0lM4Az8fg%2BMXfrtr%2ByGIBjeJG3ImLJtmtbGT74A%2F%2Bm32RcNErK3cUQC5EU4I2G8MWWJTati6P7%2BcJ4nYFrxLJCfEI8qx5bR7OX3bhycjoGxGdgI67zy01r3507sEZX7RjKJ3fg%3D%3D: ('Connection aborted.', ConnectionResetError(54, 'Connection reset by peer'))
2024-04-24 17:33:03,608 ERROR   wandb-upload_2:40667 [internal_api.py:upload_file():2769] upload_file request headers: {'User-Agent': 'python-requests/2.31.0', 'Accept-Encoding': 'gzip, deflate, br', 'Accept': '*/*', 'Connection': 'keep-alive', 'Content-MD5': '9n3qRdGj7khJIjURD1DNPA==', 'Content-Type': 'application/json', 'Content-Length': '23218'}
2024-04-24 17:33:03,608 ERROR   wandb-upload_2:40667 [internal_api.py:upload_file():2771] upload_file response body: 
2024-04-24 17:33:03,608 INFO    wandb-upload_2:40667 [retry.py:__call__():172] Retry attempt failed:
Traceback (most recent call last):
  File "/Users/a58/anaconda3/envs/llama_factory/lib/python3.10/site-packages/urllib3/connectionpool.py", line 703, in urlopen
    httplib_response = self._make_request(
  File "/Users/a58/anaconda3/envs/llama_factory/lib/python3.10/site-packages/urllib3/connectionpool.py", line 386, in _make_request
    self._validate_conn(conn)
  File "/Users/a58/anaconda3/envs/llama_factory/lib/python3.10/site-packages/urllib3/connectionpool.py", line 1042, in _validate_conn
    conn.connect()
  File "/Users/a58/anaconda3/envs/llama_factory/lib/python3.10/site-packages/urllib3/connection.py", line 419, in connect
    self.sock = ssl_wrap_socket(
  File "/Users/a58/anaconda3/envs/llama_factory/lib/python3.10/site-packages/urllib3/util/ssl_.py", line 449, in ssl_wrap_socket
    ssl_sock = _ssl_wrap_socket_impl(
  File "/Users/a58/anaconda3/envs/llama_factory/lib/python3.10/site-packages/urllib3/util/ssl_.py", line 493, in _ssl_wrap_socket_impl
    return ssl_context.wrap_socket(sock, server_hostname=server_hostname)
  File "/Users/a58/anaconda3/envs/llama_factory/lib/python3.10/ssl.py", line 513, in wrap_socket
    return self.sslsocket_class._create(
  File "/Users/a58/anaconda3/envs/llama_factory/lib/python3.10/ssl.py", line 1104, in _create
    self.do_handshake()
  File "/Users/a58/anaconda3/envs/llama_factory/lib/python3.10/ssl.py", line 1375, in do_handshake
    self._sslobj.do_handshake()
ConnectionResetError: [Errno 54] Connection reset by peer

During handling of the above exception, another exception occurred:

Traceback (most recent call last):
  File "/Users/a58/anaconda3/envs/llama_factory/lib/python3.10/site-packages/requests/adapters.py", line 486, in send
    resp = conn.urlopen(
  File "/Users/a58/anaconda3/envs/llama_factory/lib/python3.10/site-packages/urllib3/connectionpool.py", line 787, in urlopen
    retries = retries.increment(
  File "/Users/a58/anaconda3/envs/llama_factory/lib/python3.10/site-packages/urllib3/util/retry.py", line 550, in increment
    raise six.reraise(type(error), error, _stacktrace)
  File "/Users/a58/anaconda3/envs/llama_factory/lib/python3.10/site-packages/urllib3/packages/six.py", line 769, in reraise
    raise value.with_traceback(tb)
  File "/Users/a58/anaconda3/envs/llama_factory/lib/python3.10/site-packages/urllib3/connectionpool.py", line 703, in urlopen
    httplib_response = self._make_request(
  File "/Users/a58/anaconda3/envs/llama_factory/lib/python3.10/site-packages/urllib3/connectionpool.py", line 386, in _make_request
    self._validate_conn(conn)
  File "/Users/a58/anaconda3/envs/llama_factory/lib/python3.10/site-packages/urllib3/connectionpool.py", line 1042, in _validate_conn
    conn.connect()
  File "/Users/a58/anaconda3/envs/llama_factory/lib/python3.10/site-packages/urllib3/connection.py", line 419, in connect
    self.sock = ssl_wrap_socket(
  File "/Users/a58/anaconda3/envs/llama_factory/lib/python3.10/site-packages/urllib3/util/ssl_.py", line 449, in ssl_wrap_socket
    ssl_sock = _ssl_wrap_socket_impl(
  File "/Users/a58/anaconda3/envs/llama_factory/lib/python3.10/site-packages/urllib3/util/ssl_.py", line 493, in _ssl_wrap_socket_impl
    return ssl_context.wrap_socket(sock, server_hostname=server_hostname)
  File "/Users/a58/anaconda3/envs/llama_factory/lib/python3.10/ssl.py", line 513, in wrap_socket
    return self.sslsocket_class._create(
  File "/Users/a58/anaconda3/envs/llama_factory/lib/python3.10/ssl.py", line 1104, in _create
    self.do_handshake()
  File "/Users/a58/anaconda3/envs/llama_factory/lib/python3.10/ssl.py", line 1375, in do_handshake
    self._sslobj.do_handshake()
urllib3.exceptions.ProtocolError: ('Connection aborted.', ConnectionResetError(54, 'Connection reset by peer'))

During handling of the above exception, another exception occurred:

Traceback (most recent call last):
  File "/Users/a58/anaconda3/envs/llama_factory/lib/python3.10/site-packages/wandb/sdk/internal/internal_api.py", line 2760, in upload_file
    response = self._upload_file_session.put(
  File "/Users/a58/anaconda3/envs/llama_factory/lib/python3.10/site-packages/requests/sessions.py", line 649, in put
    return self.request("PUT", url, data=data, **kwargs)
  File "/Users/a58/anaconda3/envs/llama_factory/lib/python3.10/site-packages/requests/sessions.py", line 589, in request
    resp = self.send(prep, **send_kwargs)
  File "/Users/a58/anaconda3/envs/llama_factory/lib/python3.10/site-packages/requests/sessions.py", line 703, in send
    r = adapter.send(request, **kwargs)
  File "/Users/a58/anaconda3/envs/llama_factory/lib/python3.10/site-packages/requests/adapters.py", line 501, in send
    raise ConnectionError(err, request=request)
requests.exceptions.ConnectionError: ('Connection aborted.', ConnectionResetError(54, 'Connection reset by peer'))

During handling of the above exception, another exception occurred:

Traceback (most recent call last):
  File "/Users/a58/anaconda3/envs/llama_factory/lib/python3.10/site-packages/wandb/sdk/lib/retry.py", line 131, in __call__
    result = self._call_fn(*args, **kwargs)
  File "/Users/a58/anaconda3/envs/llama_factory/lib/python3.10/site-packages/wandb/sdk/internal/internal_api.py", line 2791, in upload_file
    raise _e.with_traceback(sys.exc_info()[2])
  File "/Users/a58/anaconda3/envs/llama_factory/lib/python3.10/site-packages/wandb/sdk/internal/internal_api.py", line 2760, in upload_file
    response = self._upload_file_session.put(
  File "/Users/a58/anaconda3/envs/llama_factory/lib/python3.10/site-packages/requests/sessions.py", line 649, in put
    return self.request("PUT", url, data=data, **kwargs)
  File "/Users/a58/anaconda3/envs/llama_factory/lib/python3.10/site-packages/requests/sessions.py", line 589, in request
    resp = self.send(prep, **send_kwargs)
  File "/Users/a58/anaconda3/envs/llama_factory/lib/python3.10/site-packages/requests/sessions.py", line 703, in send
    r = adapter.send(request, **kwargs)
  File "/Users/a58/anaconda3/envs/llama_factory/lib/python3.10/site-packages/requests/adapters.py", line 501, in send
    raise ConnectionError(err, request=request)
wandb.sdk.lib.retry.TransientError: None
2024-04-24 17:33:03,609 ERROR   wandb-upload_2:40667 [upload_job.py:push():74] Failed to upload file: /var/folders/0t/wpjq3m9x0s39k2ngjkd8dqj80000gn/T/tmpofojy5xl/wandb-job.json
Traceback (most recent call last):
  File "/Users/a58/anaconda3/envs/llama_factory/lib/python3.10/site-packages/urllib3/connectionpool.py", line 703, in urlopen
    httplib_response = self._make_request(
  File "/Users/a58/anaconda3/envs/llama_factory/lib/python3.10/site-packages/urllib3/connectionpool.py", line 386, in _make_request
    self._validate_conn(conn)
  File "/Users/a58/anaconda3/envs/llama_factory/lib/python3.10/site-packages/urllib3/connectionpool.py", line 1042, in _validate_conn
    conn.connect()
  File "/Users/a58/anaconda3/envs/llama_factory/lib/python3.10/site-packages/urllib3/connection.py", line 419, in connect
    self.sock = ssl_wrap_socket(
  File "/Users/a58/anaconda3/envs/llama_factory/lib/python3.10/site-packages/urllib3/util/ssl_.py", line 449, in ssl_wrap_socket
    ssl_sock = _ssl_wrap_socket_impl(
  File "/Users/a58/anaconda3/envs/llama_factory/lib/python3.10/site-packages/urllib3/util/ssl_.py", line 493, in _ssl_wrap_socket_impl
    return ssl_context.wrap_socket(sock, server_hostname=server_hostname)
  File "/Users/a58/anaconda3/envs/llama_factory/lib/python3.10/ssl.py", line 513, in wrap_socket
    return self.sslsocket_class._create(
  File "/Users/a58/anaconda3/envs/llama_factory/lib/python3.10/ssl.py", line 1104, in _create
    self.do_handshake()
  File "/Users/a58/anaconda3/envs/llama_factory/lib/python3.10/ssl.py", line 1375, in do_handshake
    self._sslobj.do_handshake()
ConnectionResetError: [Errno 54] Connection reset by peer

During handling of the above exception, another exception occurred:

Traceback (most recent call last):
  File "/Users/a58/anaconda3/envs/llama_factory/lib/python3.10/site-packages/requests/adapters.py", line 486, in send
    resp = conn.urlopen(
  File "/Users/a58/anaconda3/envs/llama_factory/lib/python3.10/site-packages/urllib3/connectionpool.py", line 787, in urlopen
    retries = retries.increment(
  File "/Users/a58/anaconda3/envs/llama_factory/lib/python3.10/site-packages/urllib3/util/retry.py", line 550, in increment
    raise six.reraise(type(error), error, _stacktrace)
  File "/Users/a58/anaconda3/envs/llama_factory/lib/python3.10/site-packages/urllib3/packages/six.py", line 769, in reraise
    raise value.with_traceback(tb)
  File "/Users/a58/anaconda3/envs/llama_factory/lib/python3.10/site-packages/urllib3/connectionpool.py", line 703, in urlopen
    httplib_response = self._make_request(
  File "/Users/a58/anaconda3/envs/llama_factory/lib/python3.10/site-packages/urllib3/connectionpool.py", line 386, in _make_request
    self._validate_conn(conn)
  File "/Users/a58/anaconda3/envs/llama_factory/lib/python3.10/site-packages/urllib3/connectionpool.py", line 1042, in _validate_conn
    conn.connect()
  File "/Users/a58/anaconda3/envs/llama_factory/lib/python3.10/site-packages/urllib3/connection.py", line 419, in connect
    self.sock = ssl_wrap_socket(
  File "/Users/a58/anaconda3/envs/llama_factory/lib/python3.10/site-packages/urllib3/util/ssl_.py", line 449, in ssl_wrap_socket
    ssl_sock = _ssl_wrap_socket_impl(
  File "/Users/a58/anaconda3/envs/llama_factory/lib/python3.10/site-packages/urllib3/util/ssl_.py", line 493, in _ssl_wrap_socket_impl
    return ssl_context.wrap_socket(sock, server_hostname=server_hostname)
  File "/Users/a58/anaconda3/envs/llama_factory/lib/python3.10/ssl.py", line 513, in wrap_socket
    return self.sslsocket_class._create(
  File "/Users/a58/anaconda3/envs/llama_factory/lib/python3.10/ssl.py", line 1104, in _create
    self.do_handshake()
  File "/Users/a58/anaconda3/envs/llama_factory/lib/python3.10/ssl.py", line 1375, in do_handshake
    self._sslobj.do_handshake()
urllib3.exceptions.ProtocolError: ('Connection aborted.', ConnectionResetError(54, 'Connection reset by peer'))

During handling of the above exception, another exception occurred:

Traceback (most recent call last):
  File "/Users/a58/anaconda3/envs/llama_factory/lib/python3.10/site-packages/wandb/sdk/internal/internal_api.py", line 2760, in upload_file
    response = self._upload_file_session.put(
  File "/Users/a58/anaconda3/envs/llama_factory/lib/python3.10/site-packages/requests/sessions.py", line 649, in put
    return self.request("PUT", url, data=data, **kwargs)
  File "/Users/a58/anaconda3/envs/llama_factory/lib/python3.10/site-packages/requests/sessions.py", line 589, in request
    resp = self.send(prep, **send_kwargs)
  File "/Users/a58/anaconda3/envs/llama_factory/lib/python3.10/site-packages/requests/sessions.py", line 703, in send
    r = adapter.send(request, **kwargs)
  File "/Users/a58/anaconda3/envs/llama_factory/lib/python3.10/site-packages/requests/adapters.py", line 501, in send
    raise ConnectionError(err, request=request)
requests.exceptions.ConnectionError: ('Connection aborted.', ConnectionResetError(54, 'Connection reset by peer'))

During handling of the above exception, another exception occurred:

Traceback (most recent call last):
  File "/Users/a58/anaconda3/envs/llama_factory/lib/python3.10/site-packages/wandb/sdk/lib/retry.py", line 131, in __call__
    result = self._call_fn(*args, **kwargs)
  File "/Users/a58/anaconda3/envs/llama_factory/lib/python3.10/site-packages/wandb/sdk/internal/internal_api.py", line 2791, in upload_file
    raise _e.with_traceback(sys.exc_info()[2])
  File "/Users/a58/anaconda3/envs/llama_factory/lib/python3.10/site-packages/wandb/sdk/internal/internal_api.py", line 2760, in upload_file
    response = self._upload_file_session.put(
  File "/Users/a58/anaconda3/envs/llama_factory/lib/python3.10/site-packages/requests/sessions.py", line 649, in put
    return self.request("PUT", url, data=data, **kwargs)
  File "/Users/a58/anaconda3/envs/llama_factory/lib/python3.10/site-packages/requests/sessions.py", line 589, in request
    resp = self.send(prep, **send_kwargs)
  File "/Users/a58/anaconda3/envs/llama_factory/lib/python3.10/site-packages/requests/sessions.py", line 703, in send
    r = adapter.send(request, **kwargs)
  File "/Users/a58/anaconda3/envs/llama_factory/lib/python3.10/site-packages/requests/adapters.py", line 501, in send
    raise ConnectionError(err, request=request)
wandb.sdk.lib.retry.TransientError: None

During handling of the above exception, another exception occurred:

Traceback (most recent call last):
  File "/Users/a58/anaconda3/envs/llama_factory/lib/python3.10/site-packages/wandb/apis/normalize.py", line 41, in wrapper
    return func(*args, **kwargs)
  File "/Users/a58/anaconda3/envs/llama_factory/lib/python3.10/site-packages/wandb/sdk/lib/retry.py", line 212, in wrapped_fn
    return retrier(*args, **kargs)
  File "/Users/a58/anaconda3/envs/llama_factory/lib/python3.10/site-packages/wandb/sdk/lib/retry.py", line 183, in __call__
    wandb.termlog(
  File "/Users/a58/anaconda3/envs/llama_factory/lib/python3.10/site-packages/wandb/errors/term.py", line 39, in termlog
    _log(
  File "/Users/a58/anaconda3/envs/llama_factory/lib/python3.10/site-packages/wandb/errors/term.py", line 95, in _log
    click.echo(line, file=sys.stderr, nl=newline)
  File "/Users/a58/anaconda3/envs/llama_factory/lib/python3.10/site-packages/click/utils.py", line 318, in echo
    file.write(out)  # type: ignore
  File "/Users/a58/anaconda3/envs/llama_factory/lib/python3.10/site-packages/debugpy/_vendored/pydevd/_pydevd_bundle/pydevd_io.py", line 40, in write
    r.write(s)
OSError: [Errno 5] Input/output error

During handling of the above exception, another exception occurred:

Traceback (most recent call last):
  File "/Users/a58/anaconda3/envs/llama_factory/lib/python3.10/site-packages/wandb/filesync/upload_job.py", line 69, in push
    deduped = self.save_fn(
  File "/Users/a58/anaconda3/envs/llama_factory/lib/python3.10/site-packages/wandb/sdk/artifacts/artifact_saver.py", line 175, in <lambda>
    lambda entry, progress_callback: self._manifest.storage_policy.store_file_sync(
  File "/Users/a58/anaconda3/envs/llama_factory/lib/python3.10/site-packages/wandb/sdk/artifacts/storage_policies/wandb_storage_policy.py", line 327, in store_file_sync
    self.default_file_upload(
  File "/Users/a58/anaconda3/envs/llama_factory/lib/python3.10/site-packages/wandb/sdk/artifacts/storage_policies/wandb_storage_policy.py", line 250, in default_file_upload
    self._api.upload_file_retry(
  File "/Users/a58/anaconda3/envs/llama_factory/lib/python3.10/site-packages/wandb/apis/normalize.py", line 87, in wrapper
    raise CommError(message, err).with_traceback(sys.exc_info()[2])
  File "/Users/a58/anaconda3/envs/llama_factory/lib/python3.10/site-packages/wandb/apis/normalize.py", line 41, in wrapper
    return func(*args, **kwargs)
  File "/Users/a58/anaconda3/envs/llama_factory/lib/python3.10/site-packages/wandb/sdk/lib/retry.py", line 212, in wrapped_fn
    return retrier(*args, **kargs)
  File "/Users/a58/anaconda3/envs/llama_factory/lib/python3.10/site-packages/wandb/sdk/lib/retry.py", line 183, in __call__
    wandb.termlog(
  File "/Users/a58/anaconda3/envs/llama_factory/lib/python3.10/site-packages/wandb/errors/term.py", line 39, in termlog
    _log(
  File "/Users/a58/anaconda3/envs/llama_factory/lib/python3.10/site-packages/wandb/errors/term.py", line 95, in _log
    click.echo(line, file=sys.stderr, nl=newline)
  File "/Users/a58/anaconda3/envs/llama_factory/lib/python3.10/site-packages/click/utils.py", line 318, in echo
    file.write(out)  # type: ignore
  File "/Users/a58/anaconda3/envs/llama_factory/lib/python3.10/site-packages/debugpy/_vendored/pydevd/_pydevd_bundle/pydevd_io.py", line 40, in write
    r.write(s)
wandb.errors.CommError: [Errno 5] Input/output error
2024-04-24 17:33:04,322 ERROR   wandb-upload_0:40667 [internal_api.py:upload_file():2767] upload_file exception https://storage.googleapis.com/wandb-production.appspot.com/darren_qing/Moe_finetuning/eqj6jv3s/wandb-metadata.json?Expires=1714037566&GoogleAccessId=gorilla-files-url-signer-man%40wandb-production.iam.gserviceaccount.com&Signature=QenUieFYHmkHYE75zginXCasU%2FtglFn9tqQAdUj4FbbBINipYA9tkPFfOvShFrMxh5tW1p0%2FZ5j1SsjEwdl4D2hk1ZdfexJ1%2F2ZYk68ukw9AHKSMBeW1JU6SFmIoQxVSy9JJraKprmxhx%2FDPCZC5bjbvbNPb47i%2BidGYKa8bgP%2Bul3txIkOlQyPZEOlRxij34JBOJegZgijdsCatpUkqH%2BAAwX%2F9A%2BoufenQZSQBd1v1FKilFFwxs8TpjWfmhz9ORxCd744GlRKjUvLLtJWgaE43%2BsLfW4PLu5u19uwokwF9Q8yAlAoWWL2e9%2BsCkIFvN5JztEbU7oxHFlhDOwRCYw%3D%3D: ('Connection aborted.', ConnectionResetError(54, 'Connection reset by peer'))
2024-04-24 17:33:04,322 ERROR   wandb-upload_0:40667 [internal_api.py:upload_file():2769] upload_file request headers: {'User-Agent': 'python-requests/2.31.0', 'Accept-Encoding': 'gzip, deflate, br', 'Accept': '*/*', 'Connection': 'keep-alive', 'Content-Length': '2451'}
2024-04-24 17:33:04,322 ERROR   wandb-upload_0:40667 [internal_api.py:upload_file():2771] upload_file response body: 
2024-04-24 17:33:04,465 ERROR   Thread-16 (_thread_body):40667 [step_upload.py:_handle_event():200] Failed to upload file: /var/folders/0t/wpjq3m9x0s39k2ngjkd8dqj80000gn/T/tmpofojy5xl/wandb-job.json
Traceback (most recent call last):
  File "/Users/a58/anaconda3/envs/llama_factory/lib/python3.10/site-packages/urllib3/connectionpool.py", line 703, in urlopen
    httplib_response = self._make_request(
  File "/Users/a58/anaconda3/envs/llama_factory/lib/python3.10/site-packages/urllib3/connectionpool.py", line 386, in _make_request
    self._validate_conn(conn)
  File "/Users/a58/anaconda3/envs/llama_factory/lib/python3.10/site-packages/urllib3/connectionpool.py", line 1042, in _validate_conn
    conn.connect()
  File "/Users/a58/anaconda3/envs/llama_factory/lib/python3.10/site-packages/urllib3/connection.py", line 419, in connect
    self.sock = ssl_wrap_socket(
  File "/Users/a58/anaconda3/envs/llama_factory/lib/python3.10/site-packages/urllib3/util/ssl_.py", line 449, in ssl_wrap_socket
    ssl_sock = _ssl_wrap_socket_impl(
  File "/Users/a58/anaconda3/envs/llama_factory/lib/python3.10/site-packages/urllib3/util/ssl_.py", line 493, in _ssl_wrap_socket_impl
    return ssl_context.wrap_socket(sock, server_hostname=server_hostname)
  File "/Users/a58/anaconda3/envs/llama_factory/lib/python3.10/ssl.py", line 513, in wrap_socket
    return self.sslsocket_class._create(
  File "/Users/a58/anaconda3/envs/llama_factory/lib/python3.10/ssl.py", line 1104, in _create
    self.do_handshake()
  File "/Users/a58/anaconda3/envs/llama_factory/lib/python3.10/ssl.py", line 1375, in do_handshake
    self._sslobj.do_handshake()
ConnectionResetError: [Errno 54] Connection reset by peer

During handling of the above exception, another exception occurred:

Traceback (most recent call last):
  File "/Users/a58/anaconda3/envs/llama_factory/lib/python3.10/site-packages/requests/adapters.py", line 486, in send
    resp = conn.urlopen(
  File "/Users/a58/anaconda3/envs/llama_factory/lib/python3.10/site-packages/urllib3/connectionpool.py", line 787, in urlopen
    retries = retries.increment(
  File "/Users/a58/anaconda3/envs/llama_factory/lib/python3.10/site-packages/urllib3/util/retry.py", line 550, in increment
    raise six.reraise(type(error), error, _stacktrace)
  File "/Users/a58/anaconda3/envs/llama_factory/lib/python3.10/site-packages/urllib3/packages/six.py", line 769, in reraise
    raise value.with_traceback(tb)
  File "/Users/a58/anaconda3/envs/llama_factory/lib/python3.10/site-packages/urllib3/connectionpool.py", line 703, in urlopen
    httplib_response = self._make_request(
  File "/Users/a58/anaconda3/envs/llama_factory/lib/python3.10/site-packages/urllib3/connectionpool.py", line 386, in _make_request
    self._validate_conn(conn)
  File "/Users/a58/anaconda3/envs/llama_factory/lib/python3.10/site-packages/urllib3/connectionpool.py", line 1042, in _validate_conn
    conn.connect()
  File "/Users/a58/anaconda3/envs/llama_factory/lib/python3.10/site-packages/urllib3/connection.py", line 419, in connect
    self.sock = ssl_wrap_socket(
  File "/Users/a58/anaconda3/envs/llama_factory/lib/python3.10/site-packages/urllib3/util/ssl_.py", line 449, in ssl_wrap_socket
    ssl_sock = _ssl_wrap_socket_impl(
  File "/Users/a58/anaconda3/envs/llama_factory/lib/python3.10/site-packages/urllib3/util/ssl_.py", line 493, in _ssl_wrap_socket_impl
    return ssl_context.wrap_socket(sock, server_hostname=server_hostname)
  File "/Users/a58/anaconda3/envs/llama_factory/lib/python3.10/ssl.py", line 513, in wrap_socket
    return self.sslsocket_class._create(
  File "/Users/a58/anaconda3/envs/llama_factory/lib/python3.10/ssl.py", line 1104, in _create
    self.do_handshake()
  File "/Users/a58/anaconda3/envs/llama_factory/lib/python3.10/ssl.py", line 1375, in do_handshake
    self._sslobj.do_handshake()
urllib3.exceptions.ProtocolError: ('Connection aborted.', ConnectionResetError(54, 'Connection reset by peer'))

During handling of the above exception, another exception occurred:

Traceback (most recent call last):
  File "/Users/a58/anaconda3/envs/llama_factory/lib/python3.10/site-packages/wandb/sdk/internal/internal_api.py", line 2760, in upload_file
    response = self._upload_file_session.put(
  File "/Users/a58/anaconda3/envs/llama_factory/lib/python3.10/site-packages/requests/sessions.py", line 649, in put
    return self.request("PUT", url, data=data, **kwargs)
  File "/Users/a58/anaconda3/envs/llama_factory/lib/python3.10/site-packages/requests/sessions.py", line 589, in request
    resp = self.send(prep, **send_kwargs)
  File "/Users/a58/anaconda3/envs/llama_factory/lib/python3.10/site-packages/requests/sessions.py", line 703, in send
    r = adapter.send(request, **kwargs)
  File "/Users/a58/anaconda3/envs/llama_factory/lib/python3.10/site-packages/requests/adapters.py", line 501, in send
    raise ConnectionError(err, request=request)
requests.exceptions.ConnectionError: ('Connection aborted.', ConnectionResetError(54, 'Connection reset by peer'))

During handling of the above exception, another exception occurred:

Traceback (most recent call last):
  File "/Users/a58/anaconda3/envs/llama_factory/lib/python3.10/site-packages/wandb/sdk/lib/retry.py", line 131, in __call__
    result = self._call_fn(*args, **kwargs)
  File "/Users/a58/anaconda3/envs/llama_factory/lib/python3.10/site-packages/wandb/sdk/internal/internal_api.py", line 2791, in upload_file
    raise _e.with_traceback(sys.exc_info()[2])
  File "/Users/a58/anaconda3/envs/llama_factory/lib/python3.10/site-packages/wandb/sdk/internal/internal_api.py", line 2760, in upload_file
    response = self._upload_file_session.put(
  File "/Users/a58/anaconda3/envs/llama_factory/lib/python3.10/site-packages/requests/sessions.py", line 649, in put
    return self.request("PUT", url, data=data, **kwargs)
  File "/Users/a58/anaconda3/envs/llama_factory/lib/python3.10/site-packages/requests/sessions.py", line 589, in request
    resp = self.send(prep, **send_kwargs)
  File "/Users/a58/anaconda3/envs/llama_factory/lib/python3.10/site-packages/requests/sessions.py", line 703, in send
    r = adapter.send(request, **kwargs)
  File "/Users/a58/anaconda3/envs/llama_factory/lib/python3.10/site-packages/requests/adapters.py", line 501, in send
    raise ConnectionError(err, request=request)
wandb.sdk.lib.retry.TransientError: None

During handling of the above exception, another exception occurred:

Traceback (most recent call last):
  File "/Users/a58/anaconda3/envs/llama_factory/lib/python3.10/site-packages/wandb/apis/normalize.py", line 41, in wrapper
    return func(*args, **kwargs)
  File "/Users/a58/anaconda3/envs/llama_factory/lib/python3.10/site-packages/wandb/sdk/lib/retry.py", line 212, in wrapped_fn
    return retrier(*args, **kargs)
  File "/Users/a58/anaconda3/envs/llama_factory/lib/python3.10/site-packages/wandb/sdk/lib/retry.py", line 183, in __call__
    wandb.termlog(
  File "/Users/a58/anaconda3/envs/llama_factory/lib/python3.10/site-packages/wandb/errors/term.py", line 39, in termlog
    _log(
  File "/Users/a58/anaconda3/envs/llama_factory/lib/python3.10/site-packages/wandb/errors/term.py", line 95, in _log
    click.echo(line, file=sys.stderr, nl=newline)
  File "/Users/a58/anaconda3/envs/llama_factory/lib/python3.10/site-packages/click/utils.py", line 318, in echo
    file.write(out)  # type: ignore
  File "/Users/a58/anaconda3/envs/llama_factory/lib/python3.10/site-packages/debugpy/_vendored/pydevd/_pydevd_bundle/pydevd_io.py", line 40, in write
    r.write(s)
OSError: [Errno 5] Input/output error

During handling of the above exception, another exception occurred:

Traceback (most recent call last):
  File "/Users/a58/anaconda3/envs/llama_factory/lib/python3.10/site-packages/wandb/filesync/upload_job.py", line 69, in push
    deduped = self.save_fn(
  File "/Users/a58/anaconda3/envs/llama_factory/lib/python3.10/site-packages/wandb/sdk/artifacts/artifact_saver.py", line 175, in <lambda>
    lambda entry, progress_callback: self._manifest.storage_policy.store_file_sync(
  File "/Users/a58/anaconda3/envs/llama_factory/lib/python3.10/site-packages/wandb/sdk/artifacts/storage_policies/wandb_storage_policy.py", line 327, in store_file_sync
    self.default_file_upload(
  File "/Users/a58/anaconda3/envs/llama_factory/lib/python3.10/site-packages/wandb/sdk/artifacts/storage_policies/wandb_storage_policy.py", line 250, in default_file_upload
    self._api.upload_file_retry(
  File "/Users/a58/anaconda3/envs/llama_factory/lib/python3.10/site-packages/wandb/apis/normalize.py", line 87, in wrapper
    raise CommError(message, err).with_traceback(sys.exc_info()[2])
  File "/Users/a58/anaconda3/envs/llama_factory/lib/python3.10/site-packages/wandb/apis/normalize.py", line 41, in wrapper
    return func(*args, **kwargs)
  File "/Users/a58/anaconda3/envs/llama_factory/lib/python3.10/site-packages/wandb/sdk/lib/retry.py", line 212, in wrapped_fn
    return retrier(*args, **kargs)
  File "/Users/a58/anaconda3/envs/llama_factory/lib/python3.10/site-packages/wandb/sdk/lib/retry.py", line 183, in __call__
    wandb.termlog(
  File "/Users/a58/anaconda3/envs/llama_factory/lib/python3.10/site-packages/wandb/errors/term.py", line 39, in termlog
    _log(
  File "/Users/a58/anaconda3/envs/llama_factory/lib/python3.10/site-packages/wandb/errors/term.py", line 95, in _log
    click.echo(line, file=sys.stderr, nl=newline)
  File "/Users/a58/anaconda3/envs/llama_factory/lib/python3.10/site-packages/click/utils.py", line 318, in echo
    file.write(out)  # type: ignore
  File "/Users/a58/anaconda3/envs/llama_factory/lib/python3.10/site-packages/debugpy/_vendored/pydevd/_pydevd_bundle/pydevd_io.py", line 40, in write
    r.write(s)
wandb.errors.CommError: [Errno 5] Input/output error

During handling of the above exception, another exception occurred:

Traceback (most recent call last):
  File "/Users/a58/anaconda3/envs/llama_factory/lib/python3.10/concurrent/futures/thread.py", line 58, in run
    result = self.fn(*self.args, **self.kwargs)
  File "/Users/a58/anaconda3/envs/llama_factory/lib/python3.10/site-packages/wandb/filesync/step_upload.py", line 288, in run_and_notify
    self._do_upload_sync(event)
  File "/Users/a58/anaconda3/envs/llama_factory/lib/python3.10/site-packages/wandb/filesync/step_upload.py", line 330, in _do_upload_sync
    job.run()
  File "/Users/a58/anaconda3/envs/llama_factory/lib/python3.10/site-packages/wandb/filesync/upload_job.py", line 57, in run
    self.push()
  File "/Users/a58/anaconda3/envs/llama_factory/lib/python3.10/site-packages/wandb/filesync/upload_job.py", line 80, in push
    wandb.termerror(
  File "/Users/a58/anaconda3/envs/llama_factory/lib/python3.10/site-packages/wandb/errors/term.py", line 61, in termerror
    _log(
  File "/Users/a58/anaconda3/envs/llama_factory/lib/python3.10/site-packages/wandb/errors/term.py", line 95, in _log
    click.echo(line, file=sys.stderr, nl=newline)
  File "/Users/a58/anaconda3/envs/llama_factory/lib/python3.10/site-packages/click/utils.py", line 318, in echo
    file.write(out)  # type: ignore
  File "/Users/a58/anaconda3/envs/llama_factory/lib/python3.10/site-packages/debugpy/_vendored/pydevd/_pydevd_bundle/pydevd_io.py", line 40, in write
    r.write(s)
OSError: [Errno 5] Input/output error
2024-04-24 17:33:23,384 ERROR   wandb-upload_0:40667 [internal_api.py:upload_file():2767] upload_file exception https://storage.googleapis.com/wandb-production.appspot.com/darren_qing/Moe_finetuning/eqj6jv3s/wandb-metadata.json?Expires=1714037566&GoogleAccessId=gorilla-files-url-signer-man%40wandb-production.iam.gserviceaccount.com&Signature=QenUieFYHmkHYE75zginXCasU%2FtglFn9tqQAdUj4FbbBINipYA9tkPFfOvShFrMxh5tW1p0%2FZ5j1SsjEwdl4D2hk1ZdfexJ1%2F2ZYk68ukw9AHKSMBeW1JU6SFmIoQxVSy9JJraKprmxhx%2FDPCZC5bjbvbNPb47i%2BidGYKa8bgP%2Bul3txIkOlQyPZEOlRxij34JBOJegZgijdsCatpUkqH%2BAAwX%2F9A%2BoufenQZSQBd1v1FKilFFwxs8TpjWfmhz9ORxCd744GlRKjUvLLtJWgaE43%2BsLfW4PLu5u19uwokwF9Q8yAlAoWWL2e9%2BsCkIFvN5JztEbU7oxHFlhDOwRCYw%3D%3D: ('Connection aborted.', ConnectionResetError(54, 'Connection reset by peer'))
2024-04-24 17:33:23,384 ERROR   wandb-upload_0:40667 [internal_api.py:upload_file():2769] upload_file request headers: {'User-Agent': 'python-requests/2.31.0', 'Accept-Encoding': 'gzip, deflate, br', 'Accept': '*/*', 'Connection': 'keep-alive', 'Content-Length': '2451'}
2024-04-24 17:33:23,385 ERROR   wandb-upload_0:40667 [internal_api.py:upload_file():2771] upload_file response body: 
2024-04-24 17:33:58,840 ERROR   wandb-upload_0:40667 [internal_api.py:upload_file():2767] upload_file exception https://storage.googleapis.com/wandb-production.appspot.com/darren_qing/Moe_finetuning/eqj6jv3s/wandb-metadata.json?Expires=1714037566&GoogleAccessId=gorilla-files-url-signer-man%40wandb-production.iam.gserviceaccount.com&Signature=QenUieFYHmkHYE75zginXCasU%2FtglFn9tqQAdUj4FbbBINipYA9tkPFfOvShFrMxh5tW1p0%2FZ5j1SsjEwdl4D2hk1ZdfexJ1%2F2ZYk68ukw9AHKSMBeW1JU6SFmIoQxVSy9JJraKprmxhx%2FDPCZC5bjbvbNPb47i%2BidGYKa8bgP%2Bul3txIkOlQyPZEOlRxij34JBOJegZgijdsCatpUkqH%2BAAwX%2F9A%2BoufenQZSQBd1v1FKilFFwxs8TpjWfmhz9ORxCd744GlRKjUvLLtJWgaE43%2BsLfW4PLu5u19uwokwF9Q8yAlAoWWL2e9%2BsCkIFvN5JztEbU7oxHFlhDOwRCYw%3D%3D: ('Connection aborted.', ConnectionResetError(54, 'Connection reset by peer'))
2024-04-24 17:33:58,840 ERROR   wandb-upload_0:40667 [internal_api.py:upload_file():2769] upload_file request headers: {'User-Agent': 'python-requests/2.31.0', 'Accept-Encoding': 'gzip, deflate, br', 'Accept': '*/*', 'Connection': 'keep-alive', 'Content-Length': '2451'}
2024-04-24 17:33:58,840 ERROR   wandb-upload_0:40667 [internal_api.py:upload_file():2771] upload_file response body: 
2024-04-24 17:35:13,322 ERROR   wandb-upload_0:40667 [internal_api.py:upload_file():2767] upload_file exception https://storage.googleapis.com/wandb-production.appspot.com/darren_qing/Moe_finetuning/eqj6jv3s/wandb-metadata.json?Expires=1714037566&GoogleAccessId=gorilla-files-url-signer-man%40wandb-production.iam.gserviceaccount.com&Signature=QenUieFYHmkHYE75zginXCasU%2FtglFn9tqQAdUj4FbbBINipYA9tkPFfOvShFrMxh5tW1p0%2FZ5j1SsjEwdl4D2hk1ZdfexJ1%2F2ZYk68ukw9AHKSMBeW1JU6SFmIoQxVSy9JJraKprmxhx%2FDPCZC5bjbvbNPb47i%2BidGYKa8bgP%2Bul3txIkOlQyPZEOlRxij34JBOJegZgijdsCatpUkqH%2BAAwX%2F9A%2BoufenQZSQBd1v1FKilFFwxs8TpjWfmhz9ORxCd744GlRKjUvLLtJWgaE43%2BsLfW4PLu5u19uwokwF9Q8yAlAoWWL2e9%2BsCkIFvN5JztEbU7oxHFlhDOwRCYw%3D%3D: ('Connection aborted.', ConnectionResetError(54, 'Connection reset by peer'))
2024-04-24 17:35:13,322 ERROR   wandb-upload_0:40667 [internal_api.py:upload_file():2769] upload_file request headers: {'User-Agent': 'python-requests/2.31.0', 'Accept-Encoding': 'gzip, deflate, br', 'Accept': '*/*', 'Connection': 'keep-alive', 'Content-Length': '2451'}
2024-04-24 17:35:13,322 ERROR   wandb-upload_0:40667 [internal_api.py:upload_file():2771] upload_file response body: 
